Workbook

Sheet SK 제외 그림 게시용
D2: 아이폰14 시리즈
C4: ▣ 아이폰 14 | F4: SK | H4: KT | J4: LG
E5: 번호이동 | F5: 카톡문의 | H5: =게시용!J40 -> 46.3 | I5: 만원 | J5: =게시용!M40 -> 68.3 | K5: 만원
E6: 기기변경 | F6: 카톡문의 | H6: =게시용!K40 -> 61.3 | I6: 만원 | J6: =게시용!N40 -> 79.3 | K6: 만원
C8: ▣ 아이폰14 + | F8: SK | H8: KT | J8: LG
E9: 번호이동 | F9: 카톡문의 | H9: =게시용!J41 -> 71.2 | I9: 만원 | J9: =게시용!M41 -> 104.8 | K9: 만원
E10: 기기변경 | F10: 카톡문의 | H10: =게시용!K41 -> 79.2 | I10: 만원 | J10: =게시용!N41 -> 113.8 | K10: 만원
C12: ▣ 아이폰14프로 | F12: SK | H12: KT | J12: LG
E13: 번호이동 | F13: 카톡문의 | H13: =게시용!J42 -> 81 | I13: 만원 | J13: =게시용!M42 -> 98 | K13: 만원
E14: 기기변경 | F14: 카톡문의 | H14: =게시용!K42 -> 91 | I14: 만원 | J14: =게시용!N42 -> 109 | K14: 만원
C16: ▣ 아이폰14프로맥스 | F16: SK | H16: KT | J16: LG
E17: 번호이동 | F17: 카톡문의 | H17: =게시용!J43 -> 116.2 | I17: 만원 | J17: =게시용!M43 -> 133.2 | K17: 만원
E18: 기기변경 | F18: 카톡문의 | H18: =게시용!K43 -> 126.2 | I18: 만원 | J18: =게시용!N43 -> 144.2 | K18: 만원
C19: ※ 공시가격 현금완납 기준입니다. 제휴카드NO,할부NO. 다른 시리즈 별도 문의 주세요.
D25: 갤럭시 폴더블 시리즈
C27: ▣ Z플립 4 | F27: SK | H27: KT | J27: LG
E28: 번호이동 | F28: 카톡문의 | H28: =게시용!J44 -> #REF! | I28: 만원 | J28: =게시용!M44 -> 재고소진 | K28: 만원
E29: 기기변경 | F29: 카톡문의 | H29: =게시용!K44 -> #REF! | I29: 만원 | J29: =게시용!N44 -> 0 | K29: 만원
C31: ▣ 폴드 4 | F31: SK | H31: KT | J31: LG
E32: 번호이동 | F32: 카톡문의 | H32: =게시용!J45 -> #REF! | I32: 만원 | J32: =게시용!M45 -> 재고소진 | K32: 만원
E33: 기기변경 | F33: 카톡문의 | H33: =게시용!K45 -> #REF! | I33: 만원 | J33: =게시용!N45 -> 0 | K33: 만원
C34: ※ 공시가격 현금완납 기준입니다. 제휴카드NO,할부NO. 다른 시리즈 별도 문의 주세요.
D38: 갤럭시 S22 시리즈
C40: ▣ S22 | F40: SK | H40: KT | J40: LG
E41: 번호이동 | F41: 카톡문의 | H41: =게시용!J46 -> SK전용모델 | I41: 만원 | J41: =게시용!M46 -> SK전용모델 | K41: 만원
E42: 기기변경 | F42: 카톡문의 | H42: =게시용!K46 -> 0 | I42: 만원 | J42: =게시용!N46 -> 0 | K42: 만원
C44: ▣ S22+ | F44: SK | H44: KT | J44: LG
E45: 번호이동 | F45: 카톡문의 | H45: =게시용!#REF! -> #REF! | I45: 만원 | J45: =게시용!#REF! -> #REF! | K45: 만원
E46: 기기변경 | F46: 카톡문의 | H46: =게시용!#REF! -> #REF! | I46: 만원 | J46: =게시용!#REF! -> #REF! | K46: 만원
C48: ▣ S22 울트라 | F48: SK | H48: KT | J48: LG
E49: 번호이동 | F49: 카톡문의 | H49: =게시용!#REF! -> #REF! | I49: 만원 | J49: =게시용!#REF! -> #REF! | K49: 만원
E50: 기기변경 | F50: 카톡문의 | H50: =게시용!#REF! -> #REF! | I50: 만원 | J50: =게시용!#REF! -> #REF! | K50: 만원
C51: ※ 공시가격 현금완납 기준입니다. 제휴카드NO,할부NO. 다른 시리즈 별도 문의 주세요.
D55: 신학기 시즌 LTE 공짜폰 특가~!
C57: ▣ NEW 키즈폰 | F57: SK | H57: KT | J57: LG
E58: 신규 | F58: 카톡문의 | H58: 0 | I58: 원 | J58: 0 | K58: 원
C59: ▣ A23 | F59: SK | H59: KT | J59: LG
E60: 신규 | F60: 카톡문의 | H60: 0 | I60: 원 | J60: 0 | K60: 원
C61: ※ 공시가격 현금완납 기준입니다. 제휴카드NO,할부NO. 다른 시리즈 별도 문의 주세요.

Sheet 그림 게시용
D3: 갤럭시 S23 시리즈
C5: ▣ S23 | F5: SK | H5: KT | J5: LG
E6: 번호이동 | F6: =게시용!G32 -> 26.7 | G6: 만원 | H6: =게시용!J32 -> 11.7 | I6: 만원 | J6: =게시용!M32 -> -5.3 | K6: 만원
E7: 기기변경 | F7: =게시용!H32 -> 53.7 | G7: 만원 | H7: =게시용!K32 -> 52.7 | I7: 만원 | J7: =게시용!N32 -> 36.7 | K7: 만원
C9: ▣ S23+ | F9: SK | H9: KT | J9: LG
E10: 번호이동 | F10: =게시용!G33 -> 81.2 | G10: 만원 | H10: =게시용!J33 -> 66.2 | I10: 만원 | J10: =게시용!M33 -> 49.2 | K10: 만원
E11: 기기변경 | F11: =게시용!H33 -> 103.2 | G11: 만원 | H11: =게시용!K33 -> 102.2 | I11: 만원 | J11: =게시용!N33 -> 90.2 | K11: 만원
C13: ▣ S23 울트라 | F13: SK | H13: KT | J13: LG
E14: 번호이동 | F14: =게시용!G34 -> 149 | G14: 만원 | H14: =게시용!J34 -> 116.9 | I14: 만원 | J14: =게시용!M34 -> 105.6 | K14: 만원
E15: 기기변경 | F15: =게시용!H34 -> 146 | G15: 만원 | H15: =게시용!K34 -> 151.9 | I15: 만원 | J15: =게시용!N34 -> 134.6 | K15: 만원
C16: ※ 공시가격 현금완납 기준입니다. 제휴카드NO,할부NO. 다른 시리즈 별도 문의 주세요.
D20: 아이폰14 시리즈
C22: ▣ 아이폰 14 | F22: SK | H22: KT | J22: LG
E23: 번호이동 | F23: =게시용!G40 -> 102.3 | G23: 만원 | H23: =게시용!J40 -> 46.3 | I23: 만원 | J23: =게시용!M40 -> 68.3 | K23: 만원
E24: 기기변경 | F24: =게시용!H40 -> 102.3 | G24: 만원 | H24: =게시용!K40 -> 61.3 | I24: 만원 | J24: =게시용!N40 -> 79.3 | K24: 만원
C26: ▣ 아이폰14 + | F26: SK | H26: KT | J26: LG
E27: 번호이동 | F27: =게시용!G41 -> 112.2 | G27: 만원 | H27: =게시용!J41 -> 71.2 | I27: 만원 | J27: =게시용!M41 -> 104.8 | K27: 만원
E28: 기기변경 | F28: =게시용!H41 -> 112.2 | G28: 만원 | H28: =게시용!K41 -> 79.2 | I28: 만원 | J28: =게시용!N41 -> 113.8 | K28: 만원
C30: ▣ 아이폰14프로 | F30: SK | H30: KT | J30: LG
E31: 번호이동 | F31: =게시용!G42 -> 132 | G31: 만원 | H31: =게시용!J42 -> 81 | I31: 만원 | J31: =게시용!M42 -> 98 | K31: 만원
E32: 기기변경 | F32: =게시용!H42 -> 132 | G32: 만원 | H32: =게시용!K42 -> 91 | I32: 만원 | J32: =게시용!N42 -> 109 | K32: 만원
C34: ▣ 아이폰14프로맥스 | F34: SK | H34: KT | J34: LG
E35: 번호이동 | F35: =게시용!G43 -> 167.2 | G35: 만원 | H35: =게시용!J43 -> 116.2 | I35: 만원 | J35: =게시용!M43 -> 133.2 | K35: 만원
E36: 기기변경 | F36: =게시용!H43 -> 167.2 | G36: 만원 | H36: =게시용!K43 -> 126.2 | I36: 만원 | J36: =게시용!N43 -> 144.2 | K36: 만원
C37: ※ 공시가격 현금완납 기준입니다. 제휴카드NO,할부NO. 다른 시리즈 별도 문의 주세요.
D43: 갤럭시 폴더블 시리즈
C45: ▣ Z플립 4 | F45: SK | H45: KT | J45: LG
E46: 번호이동 | F46: =게시용!G44 -> #REF! | G46: 만원 | H46: =게시용!J44 -> #REF! | I46: 만원 | J46: =게시용!M44 -> 재고소진 | K46: 만원
E47: 기기변경 | F47: =게시용!H44 -> #REF! | G47: 만원 | H47: =게시용!K44 -> #REF! | I47: 만원 | J47: =게시용!N44 -> 0 | K47: 만원
C49: ▣ 폴드 4 | F49: SK | H49: KT | J49: LG
E50: 번호이동 | F50: =게시용!G45 -> #REF! | G50: 만원 | H50: =게시용!J45 -> #REF! | I50: 만원 | J50: =게시용!M45 -> 재고소진 | K50: 만원
E51: 기기변경 | F51: =게시용!H45 -> #REF! | G51: 만원 | H51: =게시용!K45 -> #REF! | I51: 만원 | J51: =게시용!N45 -> 0 | K51: 만원
C52: ※ 공시가격 현금완납 기준입니다. 제휴카드NO,할부NO. 다른 시리즈 별도 문의 주세요.
D56: 갤럭시 S22 시리즈
C58: ▣ S22 | F58: SK | H58: KT | J58: LG
E59: 번호이동 | F59: =게시용!G46 -> -13.88 | G59: 만원 | H59: =게시용!J46 -> SK전용모델 | I59: 만원 | J59: =게시용!M46 -> SK전용모델 | K59: 만원
E60: 기기변경 | F60: =게시용!H46 -> 11.12 | G60: 만원 | H60: =게시용!K46 -> 0 | I60: 만원 | J60: =게시용!N46 -> 0 | K60: 만원
C62: ▣ S22+ | F62: SK | H62: KT | J62: LG
E63: 번호이동 | F63: =게시용!#REF! -> #REF! | G63: 만원 | H63: =게시용!#REF! -> #REF! | I63: 만원 | J63: =게시용!#REF! -> #REF! | K63: 만원
E64: 기기변경 | F64: =게시용!#REF! -> #REF! | G64: 만원 | H64: =게시용!#REF! -> #REF! | I64: 만원 | J64: =게시용!#REF! -> #REF! | K64: 만원
...

Sheet 게시용
B5: 현금완납 조건!! 할부 NO, 제휴카드 NO, 중고폰 반납조건 NO
B9: 구분 | C9: M+인터넷+TV = 현금 최대지급 | D9: 요금제 유지기간 | F9: 공시지원 [ D + 183일 ] 선택약정 [ D + 183일 ]
D12: 부가서비스 조건 | F12: S사 : 우주 패스(M+3) 마이스마트콜3(M+1),T ALL케어(보험)(M+1) K사 : 필수팩L(M+3), 보험(M+3) L사 : 통화편의+구글원 패키지, 폰 교체패스, V컬러링음악감상+벨링콘텐츠
B16: 5G | C16: 모델명 | D16: 출고가 | F16: S사 | I16: K사 | L16: L사
F18: 요금제 5G프리미엄(109,000) | I18: 요금제 초이스 스페셜(110,000) | L18: 요금제 기종별 상이(문의)
F20: 유리한조건 | G20: 번호이동 | H20: 기기변경 | I20: 유리한조건 | J20: 번호이동 | K20: 기기변경 | L20: 유리한조건 | M20: 번호이동 | N20: 기기변경
C22: =입력용!C13 -> 갤럭시 Z폴드7 | D22: =입력용!D13 -> 2379300 | G22: =입력용!H13*0.0001 -> 127.93 | H22: =입력용!I13*0.0001 -> 133.93 | J22: =입력용!L13*0.0001 -> 137.93 | K22: =입력용!M13*0.0001 -> 131.93 | M22: =입력용!P13*0.0001 -> 118.93 | N22: =입력용!Q13*0.0001 -> 112.93
C23: =입력용!C14 -> 갤럭시 Z플립7_256G | D23: =입력용!D14 -> 1485000 | G23: =입력용!H14*0.0001 -> 26.5 | H23: =입력용!I14*0.0001 -> 43.5 | J23: =입력용!L14*0.0001 -> 38.5 | K23: =입력용!M14*0.0001 -> 32.5 | M23: =입력용!P14*0.0001 -> 16.5 | N23: =입력용!Q14*0.0001 -> 11.5
C24: =입력용!C15 -> 갤럭시 Z플립7_512G | D24: =입력용!D15 -> 1643400 | G24: =입력용!H15*0.0001 -> 42.34 | H24: =입력용!I15*0.0001 -> 49.34 | J24: =입력용!L15*0.0001 -> 54.34 | K24: =입력용!M15*0.0001 -> 48.34 | M24: =입력용!P15*0.0001 -> 90.34 | N24: =입력용!Q15*0.0001 -> 95.34
C25: =입력용!C16 -> 갤럭시 S26_256G | D25: =입력용!D16 -> 1254000 | G25: =입력용!H16*0.0001 -> 77.4 | H25: =입력용!I16*0.0001 -> 83.4 | J25: =입력용!L16*0.0001 -> 59.3 | K25: =입력용!M16*0.0001 -> 60.3 | M25: =입력용!P16*0.0001 -> 43 | N25: =입력용!Q16*0.0001 -> 37
C26: =입력용!C17 -> 갤럭시 S26+_256G | D26: =입력용!D17 -> 1452000 | G26: =입력용!H17*0.0001 -> 97.2 | H26: =입력용!I17*0.0001 -> 103.2 | J26: =입력용!L17*0.0001 -> 79.1 | K26: =입력용!M17*0.0001 -> 80.1 | M26: =입력용!P17*0.0001 -> 62.8 | N26: =입력용!Q17*0.0001 -> 56.8
C27: =입력용!C18 -> 갤럭시 S26 울트라_256G | D27: =입력용!D18 -> 1797400 | G27: =입력용!H18*0.0001 -> 131.74 | H27: =입력용!I18*0.0001 -> 137.74 | J27: =입력용!L18*0.0001 -> 117.64 | K27: =입력용!M18*0.0001 -> 116.64 | M27: =입력용!P18*0.0001 -> 97.34 | N27: =입력용!Q18*0.0001 -> 91.34
C28: =입력용!C19 -> 갤럭시 S25 | D28: =입력용!D19 -> 1155000 | G28: =입력용!H19*0.0001 -> 60.5 | H28: =입력용!I19*0.0001 -> 65.5 | J28: =입력용!L19*0.0001 -> 51.4 | K28: =입력용!M19*0.0001 -> 62.4 | L28: =VLOOKUP(C28,#REF!,2,FALSE) -> #REF! | M28: =입력용!P19*0.0001 -> 36.1 | N28: =입력용!Q19*0.0001 -> 32.1
C29: =입력용!C20 -> 갤럭시 S25+ | D29: =입력용!D20 -> 1353000 | G29: =입력용!H20*0.0001 -> 94.3 | H29: =입력용!I20*0.0001 -> 100.3 | J29: =입력용!L20*0.0001 -> 107.2 | K29: =입력용!M20*0.0001 -> 107.2 | L29: =VLOOKUP(C29,#REF!,2,FALSE) -> #REF! | M29: =입력용!P20*0.0001 -> 103.9 | N29: =입력용!Q20*0.0001 -> 103.9
C30: =입력용!C21 -> 갤럭시 S25 울트라 | D30: =입력용!D21 -> 1698400 | G30: =입력용!H21*0.0001 -> 114.84 | H30: =입력용!I21*0.0001 -> 119.84 | J30: =입력용!L21*0.0001 -> 105.74 | K30: =입력용!M21*0.0001 -> 116.74 | L30: =VLOOKUP(C30,#REF!,2,FALSE) -> #REF! | M30: =입력용!P21*0.0001 -> 94.44 | N30: =입력용!Q21*0.0001 -> 107.44
C31: =입력용!C22 -> 갤럭시 S25 엣지 | D31: =입력용!D22 -> 1496000 | G31: =입력용!H22*0.0001 -> 42.6 | H31: =입력용!I22*0.0001 -> 47.6 | J31: =입력용!L22*0.0001 -> 37.6 | K31: =입력용!M22*0.0001 -> 29.6 | L31: =VLOOKUP(C31,#REF!,2,FALSE) -> #REF! | M31: =입력용!P22*0.0001 -> 24.6 | N31: =입력용!Q22*0.0001 -> 20.6
C32: =입력용!C23 -> 아이폰17 256G | D32: =입력용!D23 -> 1287000 | G32: =입력용!H23*0.0001 -> 26.7 | H32: =입력용!I23*0.0001 -> 53.7 | J32: =입력용!L23*0.0001 -> 11.7 | K32: =입력용!M23*0.0001 -> 52.7 | L32: =VLOOKUP(C32,#REF!,2,FALSE) -> #REF! | M32: =입력용!P23*0.0001 -> -5.3 | N32: =입력용!Q23*0.0001 -> 36.7
C33: =입력용!C25 -> 아이폰17 프로 256G | D33: =입력용!D25 -> 1782000 | G33: =입력용!H25*0.0001 -> 81.2 | H33: =입력용!I25*0.0001 -> 103.2 | J33: =입력용!L25*0.0001 -> 66.2 | K33: =입력용!M25*0.0001 -> 102.2 | L33: =VLOOKUP(C33,#REF!,2,FALSE) -> #REF! | M33: =입력용!P25*0.0001 -> 49.2 | N33: =입력용!Q25*0.0001 -> 90.2
C34: =입력용!C26 -> 아이폰17 프로맥스 256G | D34: =입력용!D26 -> 1980000 | G34: =입력용!H26*0.0001 -> 149 | H34: =입력용!I26*0.0001 -> 146 | J34: =입력용!L26*0.0001 -> 116.9 | K34: =입력용!M26*0.0001 -> 151.9 | L34: =VLOOKUP(C34,#REF!,2,FALSE) -> #REF! | M34: =입력용!P26*0.0001 -> 105.6 | N34: =입력용!Q26*0.0001 -> 134.6
C35: =입력용!C31 -> 갤럭시 S25FE | D35: =입력용!D31 -> 946000 | G35: =입력용!H31*0.0001 -> -21.4 | H35: =입력용!I31*0.0001 -> -0.4 | J35: =입력용!L31*0.0001 -> 3.6 | K35: =입력용!M31*0.0001 -> 6.6 | L35: =VLOOKUP(C35,#REF!,2,FALSE) -> #REF! | M35: =입력용!P31*0.0001 -> -27.4 | N35: =입력용!Q31*0.0001 -> 2.6
C36: =입력용!C23 -> 아이폰17 256G | D36: =입력용!D23 -> 1287000 | G36: =입력용!H23*0.0001 -> 26.7 | H36: =입력용!I23*0.0001 -> 53.7 | I36: =입력용!J23*0.0001 -> 45 | J36: =입력용!L23*0.0001 -> 11.7 | K36: =입력용!M23*0.0001 -> 52.7 | L36: =입력용!M23*0.0001 -> 52.7 | M36: =입력용!P23*0.0001 -> -5.3 | N36: =입력용!Q23*0.0001 -> 36.7
C37: =입력용!C24 -> 아이폰17 에어 256G | D37: =입력용!D24 -> 1584000 | G37: =입력용!H24*0.0001 -> 53.4 | H37: =입력용!I24*0.0001 -> 83.4 | I37: =입력용!J24*0.0001 -> 45 | J37: =입력용!L24*0.0001 -> 46.4 | K37: =입력용!M24*0.0001 -> 82.4 | L37: =입력용!M24*0.0001 -> 82.4 | M37: =입력용!P24*0.0001 -> 24.4 | N37: =입력용!Q24*0.0001 -> 66.4
C38: =입력용!C25 -> 아이폰17 프로 256G | D38: =입력용!D25 -> 1782000 | G38: =입력용!H25*0.0001 -> 81.2 | H38: =입력용!I25*0.0001 -> 103.2 | I38: =입력용!J25*0.0001 -> 45 | J38: =입력용!L25*0.0001 -> 66.2 | K38: =입력용!M25*0.0001 -> 102.2 | L38: =입력용!M25*0.0001 -> 102.2 | M38: =입력용!P25*0.0001 -> 49.2 | N38: =입력용!Q25*0.0001 -> 90.2
C39: =입력용!C26 -> 아이폰17 프로맥스 256G | D39: =입력용!D26 -> 1980000 | G39: =입력용!H26*0.0001 -> 149 | H39: =입력용!I26*0.0001 -> 146 | I39: =입력용!J26*0.0001 -> 20.1 | J39: =입력용!L26*0.0001 -> 116.9 | K39: =입력용!M26*0.0001 -> 151.9 | L39: =입력용!M26*0.0001 -> 151.9 | M39: =입력용!P26*0.0001 -> 105.6 | N39: =입력용!Q26*0.0001 -> 134.6
C40: =입력용!C27 -> 아이폰16 128G | D40: =입력용!D27 -> 1243000 | G40: =입력용!H27*0.0001 -> 102.3 | H40: =입력용!I27*0.0001 -> 102.3 | I40: =VLOOKUP(C40,#REF!,2,FALSE) -> #REF! | J40: =입력용!L27*0.0001 -> 46.3 | K40: =입력용!M27*0.0001 -> 61.3 | L40: =VLOOKUP(C40,#REF!,2,FALSE) -> #REF! | M40: =입력용!P27*0.0001 -> 68.3 | N40: =입력용!Q27*0.0001 -> 79.3
C41: =입력용!C28 -> 아이폰16+ 128G | D41: =입력용!D28 -> 1342000 | G41: =입력용!H28*0.0001 -> 112.2 | H41: =입력용!I28*0.0001 -> 112.2 | I41: =VLOOKUP(C41,#REF!,2,FALSE) -> #REF! | J41: =입력용!L28*0.0001 -> 71.2 | K41: =입력용!M28*0.0001 -> 79.2 | L41: =VLOOKUP(C41,#REF!,2,FALSE) -> #REF! | M41: =입력용!P28*0.0001 -> 104.8 | N41: =입력용!Q28*0.0001 -> 113.8
C42: =입력용!C29 -> 아이폰16 프로 128G | D42: =입력용!D29 -> 1540000 | G42: =입력용!H29*0.0001 -> 132 | H42: =입력용!I29*0.0001 -> 132 | I42: =VLOOKUP(C42,#REF!,2,FALSE) -> #REF! | J42: =입력용!L29*0.0001 -> 81 | K42: =입력용!M29*0.0001 -> 91 | L42: =VLOOKUP(C42,#REF!,2,FALSE) -> #REF! | M42: =입력용!P29*0.0001 -> 98 | N42: =입력용!Q29*0.0001 -> 109
C43: =입력용!C30 -> 아이폰16 프로맥스 256G | D43: =입력용!D30 -> 1892000 | G43: =입력용!H30*0.0001 -> 167.2 | H43: =입력용!I30*0.0001 -> 167.2 | I43: =VLOOKUP(C43,#REF!,2,FALSE) -> #REF! | J43: =입력용!L30*0.0001 -> 116.2 | K43: =입력용!M30*0.0001 -> 126.2 | L43: =VLOOKUP(C43,#REF!,2,FALSE) -> #REF! | M43: =입력용!P30*0.0001 -> 133.2 | N43: =입력용!Q30*0.0001 -> 144.2
C44: =입력용!#REF! -> #REF! | D44: =입력용!#REF! -> #REF! | G44: =입력용!#REF!*0.0001 -> #REF! | H44: =입력용!#REF!*0.0001 -> #REF! | I44: =VLOOKUP(C44,#REF!,2,FALSE) -> #REF! | J44: =입력용!#REF!*0.0001 -> #REF! | K44: =입력용!#REF!*0.0001 -> #REF! | L44: =VLOOKUP(C44,#REF!,2,FALSE) -> #REF! | M44: 재고소진
C45: =입력용!#REF! -> #REF! | D45: =입력용!#REF! -> #REF! | G45: =입력용!#REF!*0.0001 -> #REF! | H45: =입력용!#REF!*0.0001 -> #REF! | I45: =VLOOKUP(C45,#REF!,2,FALSE) -> #REF! | J45: =입력용!#REF!*0.0001 -> #REF! | K45: =입력용!#REF!*0.0001 -> #REF! | L45: =VLOOKUP(C45,#REF!,2,FALSE) -> #REF! | M45: 재고소진
C46: =입력용!C32 -> 퀀텀6(A566) | D46: =입력용!D32 -> 618200 | F46: =VLOOKUP(C46,입력용!C:G,5,FALSE) -> 0 | G46: =입력용!H32*0.0001 -> -13.88 | H46: =입력용!I32*0.0001 -> 11.12 | I46: =입력용!J32*0.0001 -> 0 | J46: SK전용모델 | L46: =입력용!L32*0.0001 -> 59.82 | M46: SK전용모델
F47: =VLOOKUP(C47,입력용!C:G,5,FALSE) -> #N/A | I47: =입력용!J33*0.0001 -> 43.5 | L47: =입력용!L33*0.0001 -> -33.56
D48: =입력용!#REF! -> #REF! | F48: =VLOOKUP(C48,입력용!C:G,5,FALSE) -> #N/A | G48: 재고소진 | I48: =VLOOKUP(C48,#REF!,2,FALSE) -> #REF! | J48: 재고소진 | L48: =VLOOKUP(C48,#REF!,2,FALSE) -> #REF! | M48: 재고소진
C49: =입력용!#REF! -> #REF! | D49: =입력용!#REF! -> #REF! | F49: =VLOOKUP(C49,입력용!C:G,5,FALSE) -> #REF! | G49: =입력용!#REF!*0.0001 -> #REF! | H49: =입력용!#REF!*0.0001 -> #REF! | I49: =VLOOKUP(C49,#REF!,2,FALSE) -> #REF! | J49: =입력용!#REF!*0.0001 -> #REF! | K49: =입력용!#REF!*0.0001 -> #REF! | L49: =VLOOKUP(C49,#REF!,2,FALSE) -> #REF! | M49: =입력용!#REF!*0.0001 -> #REF! | N49: =입력용!#REF!*0.0001 -> #REF!
C50: =입력용!#REF! -> #REF! | D50: =입력용!#REF! -> #REF! | F50: =VLOOKUP(C50,입력용!C:G,5,FALSE) -> #REF! | G50: =입력용!#REF!*0.0001 -> #REF! | H50: =입력용!#REF!*0.0001 -> #REF! | I50: =VLOOKUP(C50,#REF!,2,FALSE) -> #REF! | J50: =입력용!#REF!*0.0001 -> #REF! | K50: =입력용!#REF!*0.0001 -> #REF! | L50: =VLOOKUP(C50,#REF!,2,FALSE) -> #REF! | M50: =입력용!#REF!*0.0001 -> #REF! | N50: =입력용!#REF!*0.0001 -> #REF!
C51: =입력용!#REF! -> #REF! | D51: =입력용!#REF! -> #REF! | F51: =VLOOKUP(C51,입력용!C:G,5,FALSE) -> #REF! | G51: =입력용!#REF!*0.0001 -> #REF! | H51: =입력용!#REF!*0.0001 -> #REF! | I51: =VLOOKUP(C51,#REF!,2,FALSE) -> #REF! | J51: 재고소진 | L51: =VLOOKUP(C51,#REF!,2,FALSE) -> #REF! | M51: 재고소진
C52: =입력용!#REF! -> #REF! | D52: =입력용!#REF! -> #REF! | F52: =VLOOKUP(C52,입력용!C:G,5,FALSE) -> #REF! | G52: =입력용!#REF!*0.0001 -> #REF! | H52: =입력용!#REF!*0.0001 -> #REF! | I52: =VLOOKUP(C52,#REF!,2,FALSE) -> #REF! | J52: 재고소진 | L52: =VLOOKUP(C52,#REF!,2,FALSE) -> #REF! | M52: 재고소진
C53: =입력용!#REF! -> #REF! | D53: =입력용!#REF! -> #REF! | F53: 공시지원 | G53: =입력용!#REF!*0.0001 -> #REF! | H53: =입력용!#REF!*0.0001 -> #REF! | I53: =VLOOKUP(C53,#REF!,2,FALSE) -> #REF! | J53: =입력용!#REF!*0.0001 -> #REF! | K53: =입력용!#REF!*0.0001 -> #REF! | L53: =VLOOKUP(C53,#REF!,2,FALSE) -> #REF! | M53: 재고소진
C54: =입력용!#REF! -> #REF! | D54: =입력용!#REF! -> #REF! | F54: =VLOOKUP(C54,입력용!C:G,5,FALSE) -> #REF! | G54: 재고소진 | I54: =VLOOKUP(C54,#REF!,2,FALSE) -> #REF! | J54: 재고소진 | L54: =VLOOKUP(C54,#REF!,2,FALSE) -> #REF! | M54: 재고소진
C55: =입력용!#REF! -> #REF! | D55: =입력용!#REF! -> #REF! | F55: =VLOOKUP(C55,입력용!C:G,5,FALSE) -> #REF! | G55: =입력용!#REF!*0.0001 -> #REF! | H55: =입력용!#REF!*0.0001 -> #REF! | I55: =VLOOKUP(C55,#REF!,2,FALSE) -> #REF! | J55: =입력용!#REF!*0.0001 -> #REF! | K55: =입력용!#REF!*0.0001 -> #REF! | L55: =VLOOKUP(C55,#REF!,2,FALSE) -> #REF! | M55: =입력용!#REF!*0.0001 -> #REF! | N55: =입력용!#REF!*0.0001 -> #REF!
...

Sheet 입력용
B6: 5G | D6: 출고가 | F6: SKT | J6: KT | N6: LG U+ | R6: 공시 타점입력 | X6: SK합산단가 단가 우위 거래처 | AF6: 모델명 | AG6: KT합산단가 단가 우위 거래처 | AO6: 모델명 | AP6: LG합산단가 단가 우위 거래처
F8: 공통지원금 | G8: MNP지원금 | H8: 요금제 5G프리미엄 (109,000원)기준 | J8: 공통지원금 | K8: MNP지원금 | L8: 요금제 초이스스페셜(110,000원)기준 | N8: 공통지원금 | O8: MNP지원금 | P8: 요금제 5G프리미어슈퍼(115,000원)기준 | R8: SK | T8: KT | V8: LG
R10: 번호이동 | S10: 기기변경 | T10: 번호이동 | U10: 기기변경 | V10: 번호이동 | W10: 기기변경 | X10: MNP | AB10: 기변 | AG10: MNP | AK10: 기변 | AP10: MNP | AT10: 기변
H11: 번호이동 | I11: 기기변경 | L11: 번호이동 | M11: 기기변경 | P11: 번호이동 | Q11: 기기변경 | X11: 공시 | Z11: 선약 | AB11: 공시 | AD11: 선약 | AG11: 공시 | AI11: 선약 | AK11: 공시 | AM11: 선약 | AP11: 공시 | AR11: 선약 | AT11: 공시 | AV11: 선약
X12: 총리베 | Y12: 거래처 | Z12: 총리베 | AA12: 거래처 | AB12: 총리베 | AC12: 거래처 | AD12: 총리베 | AE12: 거래처 | AG12: 총리베 | AH12: 거래처 | AI12: 총리베 | AJ12: 거래처 | AK12: 총리베 | AL12: 거래처 | AM12: 총리베 | AN12: 거래처 | AP12: 총리베 | AQ12: 거래처 | AR12: 총리베 | AS12: 거래처 | AT12: 총리베 | AU12: 거래처 | AV12: 총리베 | AW12: 거래처
C13: 갤럭시 Z폴드7 | D13: 2379300 | F13: 500000 | H13: =SUM(D13-F13-G13)-SUM(X13-R13) -> 1279300 | I13: =SUM(D13-F13)-SUM(AB13-S13) -> 1339300 | J13: 500000 | L13: =SUM(D13-J13-K13)-SUM(AG13-T13) -> 1379300 | M13: =SUM(D13-J13)-SUM(AK13-U13) -> 1319300 | N13: 500000 | P13: =SUM(D13-N13-O13)-SUM(AP13-V13) -> 1189300 | Q13: =SUM(D13-N13)-SUM(AT13-W13) -> 1129300 | R13: 0 | S13: 0 | T13: 0 | U13: 0 | V13: 0 | W13: 0 | X13: =MAX(SK합산단가입력!W8:Y8) -> 600000 | Y13: =IF(SK합산단가입력!W8=입력용!X13,"블루",IF(SK합산단가입력!X8=입력용!X13,"MSC","한음")) -> 블루 | Z13: =MAX(SK합산단가입력!Z8:AB8) -> 550000 | AA13: =IF(SK합산단가입력!Z8=입력용!Z13,"블루",IF(SK합산단가입력!AA8=입력용!Z13,"MSC","한음")) -> 블루 | AB13: =MAX(SK합산단가입력!AD8:AF8) -> 540000 | AC13: =IF(SK합산단가입력!AD8=입력용!AB13,"블루",IF(SK합산단가입력!AE8=입력용!AB13,"MSC","MSC")) -> MSC | AD13: =MAX(SK합산단가입력!AG8:AI8) -> 440000 | AE13: =IF(SK합산단가입력!AG8=입력용!AD13,"블루",IF(SK합산단가입력!AH8=입력용!AD13,"MSC","한음")) -> MSC | AF13: =C13 -> 갤럭시 Z폴드7 | AG13: =MAX('KT 합산단가입력'!Y8:AA8) -> 500000 | AH13: =IF('KT 합산단가입력'!Y8=입력용!AG13,"MNS",IF('KT 합산단가입력'!Z8=입력용!AG13,"세이프","이룸")) -> 이룸 | AI13: =MAX('KT 합산단가입력'!AB8:AD8) -> 530000 | AJ13: =IF('KT 합산단가입력'!AB8=입력용!AI13,"MNS",IF('KT 합산단가입력'!AC8=입력용!AI13,"세이프","이룸")) -> 이룸 | AK13: =MAX('KT 합산단가입력'!AF8:AH8) -> 560000 | AL13: =IF('KT 합산단가입력'!AF8=입력용!AK13,"MNS",IF('KT 합산단가입력'!AG8=입력용!AK13,"세이프","이룸")) -> 이룸 | AM13: =MAX('KT 합산단가입력'!AI8:AK8) -> 590000 | AN13: =IF('KT 합산단가입력'!AI8=입력용!AM13,"MNS",IF('KT 합산단가입력'!AJ8=입력용!AM13,"세이프","이룸")) -> 이룸 | AO13: =C13 -> 갤럭시 Z폴드7 | AP13: =MAX('LG 합산단가입력'!Z8:AB8) -> 690000 | AQ13: =IF('LG 합산단가입력'!Z8=입력용!AP13,"마라톤",IF('LG 합산단가입력'!AA8=입력용!AP13,"골드","충청")) -> 충청 | AR13: =MAX('LG 합산단가입력'!AC8:AE8) -> 630000 | AS13: =IF('LG 합산단가입력'!AC8=입력용!AR13,"마라톤",IF('LG 합산단가입력'!AD8=입력용!AR13,"골드","충청")) -> 충청 | AT13: =MAX('LG 합산단가입력'!AG8:AI8) -> 750000 | AU13: =IF('LG 합산단가입력'!AG8=입력용!AT13,"마라톤",IF('LG 합산단가입력'!AH8=입력용!AT13,"골드","충청")) -> 충청 | AV13: =MAX('LG 합산단가입력'!AJ8:AL8) -> 750000 | AW13: =IF('LG 합산단가입력'!AJ8=입력용!AV13,"마라톤",IF('LG 합산단가입력'!AK8=입력용!AV13,"골드","충청")) -> 충청
C14: 갤럭시 Z플립7_256G | D14: 1485000 | F14: 600000 | H14: =SUM(D14-F14-G14)-SUM(X14-R14) -> 265000 | I14: =SUM(D14-F14)-SUM(AB14-S14) -> 435000 | J14: 600000 | L14: =SUM(D14-J14-K14)-SUM(AG14-T14) -> 385000 | M14: =SUM(D14-J14)-SUM(AK14-U14) -> 325000 | N14: 600000 | P14: =SUM(D14-N14-O14)-SUM(AP14-V14) -> 165000 | Q14: =SUM(D14-N14)-SUM(AT14-W14) -> 115000 | R14: 0 | S14: 0 | T14: 0 | U14: 0 | V14: 0 | W14: 0 | X14: =MAX(SK합산단가입력!W9:Y9) -> 620000 | Y14: =IF(SK합산단가입력!W9=입력용!X14,"블루",IF(SK합산단가입력!X9=입력용!X14,"MSC","한음")) -> 블루 | Z14: =MAX(SK합산단가입력!Z9:AB9) -> 570000 | AA14: =IF(SK합산단가입력!Z9=입력용!Z14,"블루",IF(SK합산단가입력!AA9=입력용!Z14,"MSC","한음")) -> 블루 | AB14: =MAX(SK합산단가입력!AD9:AF9) -> 450000 | AC14: =IF(SK합산단가입력!AD9=입력용!AB14,"블루",IF(SK합산단가입력!AE9=입력용!AB14,"MSC","MSC")) -> 블루 | AD14: =MAX(SK합산단가입력!AG9:AI9) -> 350000 | AE14: =IF(SK합산단가입력!AG9=입력용!AD14,"블루",IF(SK합산단가입력!AH9=입력용!AD14,"MSC","한음")) -> 블루 | AF14: =C14 -> 갤럭시 Z플립7_256G | AG14: =MAX('KT 합산단가입력'!Y9:AA9) -> 500000 | AH14: =IF('KT 합산단가입력'!Y9=입력용!AG14,"MNS",IF('KT 합산단가입력'!Z9=입력용!AG14,"세이프","이룸")) -> 이룸 | AI14: =MAX('KT 합산단가입력'!AB9:AD9) -> 530000 | AJ14: =IF('KT 합산단가입력'!AB9=입력용!AI14,"MNS",IF('KT 합산단가입력'!AC9=입력용!AI14,"세이프","이룸")) -> 이룸 | AK14: =MAX('KT 합산단가입력'!AF9:AH9) -> 560000 | AL14: =IF('KT 합산단가입력'!AF9=입력용!AK14,"MNS",IF('KT 합산단가입력'!AG9=입력용!AK14,"세이프","이룸")) -> 이룸 | AM14: =MAX('KT 합산단가입력'!AI9:AK9) -> 590000 | AN14: =IF('KT 합산단가입력'!AI9=입력용!AM14,"MNS",IF('KT 합산단가입력'!AJ9=입력용!AM14,"세이프","이룸")) -> 이룸 | AO14: =C14 -> 갤럭시 Z플립7_256G | AP14: =MAX('LG 합산단가입력'!Z9:AB9) -> 720000 | AQ14: =IF('LG 합산단가입력'!Z9=입력용!AP14,"마라톤",IF('LG 합산단가입력'!AA9=입력용!AP14,"골드","충청")) -> 마라톤 | AR14: =MAX('LG 합산단가입력'!AC9:AE9) -> 650000 | AS14: =IF('LG 합산단가입력'!AC9=입력용!AR14,"마라톤",IF('LG 합산단가입력'!AD9=입력용!AR14,"골드","충청")) -> 마라톤 | AT14: =MAX('LG 합산단가입력'!AG9:AI9) -> 770000 | AU14: =IF('LG 합산단가입력'!AG9=입력용!AT14,"마라톤",IF('LG 합산단가입력'!AH9=입력용!AT14,"골드","충청")) -> 마라톤 | AV14: =MAX('LG 합산단가입력'!AJ9:AL9) -> 770000 | AW14: =IF('LG 합산단가입력'!AJ9=입력용!AV14,"마라톤",IF('LG 합산단가입력'!AK9=입력용!AV14,"골드","충청")) -> 충청
C15: 갤럭시 Z플립7_512G | D15: 1643400 | F15: 600000 | H15: =SUM(D15-F15-G15)-SUM(X15-R15) -> 423400 | I15: =SUM(D15-F15)-SUM(AB15-S15) -> 493400 | J15: 600000 | L15: =SUM(D15-J15-K15)-SUM(AG15-T15) -> 543400 | M15: =SUM(D15-J15)-SUM(AK15-U15) -> 483400 | N15: 600000 | P15: =SUM(D15-N15-O15)-SUM(AP15-V15) -> 903400 | Q15: =SUM(D15-N15)-SUM(AT15-W15) -> 953400 | R15: 0 | S15: 0 | T15: 0 | U15: 0 | V15: 0 | W15: 0 | X15: =MAX(SK합산단가입력!W10:Y10) -> 620000 | Y15: =IF(SK합산단가입력!W10=입력용!X15,"블루",IF(SK합산단가입력!X10=입력용!X15,"MSC","한음")) -> 블루 | Z15: =MAX(SK합산단가입력!Z10:AB10) -> 570000 | AA15: =IF(SK합산단가입력!Z10=입력용!Z15,"블루",IF(SK합산단가입력!AA10=입력용!Z15,"MSC","한음")) -> 블루 | AB15: =MAX(SK합산단가입력!AD10:AF10) -> 550000 | AC15: =IF(SK합산단가입력!AD10=입력용!AB15,"블루",IF(SK합산단가입력!AE10=입력용!AB15,"MSC","MSC")) -> 블루 | AD15: =MAX(SK합산단가입력!AG10:AI10) -> 450000 | AE15: =IF(SK합산단가입력!AG10=입력용!AD15,"블루",IF(SK합산단가입력!AH10=입력용!AD15,"MSC","한음")) -> 블루 | AF15: =C15 -> 갤럭시 Z플립7_512G | AG15: =MAX('KT 합산단가입력'!Y10:AA10) -> 500000 | AH15: =IF('KT 합산단가입력'!Y10=입력용!AG15,"MNS",IF('KT 합산단가입력'!Z10=입력용!AG15,"세이프","이룸")) -> 이룸 | AI15: =MAX('KT 합산단가입력'!AB10:AD10) -> 530000 | AJ15: =IF('KT 합산단가입력'!AB10=입력용!AI15,"MNS",IF('KT 합산단가입력'!AC10=입력용!AI15,"세이프","이룸")) -> 이룸 | AK15: =MAX('KT 합산단가입력'!AF10:AH10) -> 560000 | AL15: =IF('KT 합산단가입력'!AF10=입력용!AK15,"MNS",IF('KT 합산단가입력'!AG10=입력용!AK15,"세이프","이룸")) -> 이룸 | AM15: =MAX('KT 합산단가입력'!AI10:AK10) -> 590000 | AN15: =IF('KT 합산단가입력'!AI10=입력용!AM15,"MNS",IF('KT 합산단가입력'!AJ10=입력용!AM15,"세이프","이룸")) -> 이룸 | AO15: =C15 -> 갤럭시 Z플립7_512G | AP15: =MAX('LG 합산단가입력'!Z10:AB10) -> 140000 | AQ15: =IF('LG 합산단가입력'!Z10=입력용!AP15,"마라톤",IF('LG 합산단가입력'!AA10=입력용!AP15,"골드","충청")) -> 마라톤 | AR15: =MAX('LG 합산단가입력'!AC10:AE10) -> 70000 | AS15: =IF('LG 합산단가입력'!AC10=입력용!AR15,"마라톤",IF('LG 합산단가입력'!AD10=입력용!AR15,"골드","충청")) -> 마라톤 | AT15: =MAX('LG 합산단가입력'!AG10:AI10) -> 90000 | AU15: =IF('LG 합산단가입력'!AG10=입력용!AT15,"마라톤",IF('LG 합산단가입력'!AH10=입력용!AT15,"골드","충청")) -> 충청 | AV15: =MAX('LG 합산단가입력'!AJ10:AL10) -> 90000 | AW15: =IF('LG 합산단가입력'!AJ10=입력용!AV15,"마라톤",IF('LG 합산단가입력'!AK10=입력용!AV15,"골드","충청")) -> 충청
C16: 갤럭시 S26_256G | D16: 1254000 | F16: 190000 | H16: =SUM(D16-F16-G16)-SUM(X16-R16) -> 774000 | I16: =SUM(D16-F16)-SUM(AB16-S16) -> 834000 | J16: 201000 | L16: =SUM(D16-J16-K16)-SUM(AG16-T16) -> 593000 | M16: =SUM(D16-J16)-SUM(AK16-U16) -> 603000 | N16: 204000 | P16: =SUM(D16-N16-O16)-SUM(AP16-V16) -> 430000 | Q16: =SUM(D16-N16)-SUM(AT16-W16) -> 370000 | R16: 0 | S16: 0 | T16: 0 | U16: 0 | V16: 0 | W16: 0 | X16: =MAX(SK합산단가입력!W11:Y11) -> 290000 | Y16: =IF(SK합산단가입력!W11=입력용!X16,"블루",IF(SK합산단가입력!X11=입력용!X16,"MSC","한음")) -> 블루 | Z16: =MAX(SK합산단가입력!Z11:AB11) -> 510000 | AA16: =IF(SK합산단가입력!Z11=입력용!Z16,"블루",IF(SK합산단가입력!AA11=입력용!Z16,"MSC","한음")) -> 블루 | AB16: =MAX(SK합산단가입력!AD11:AF11) -> 230000 | AC16: =IF(SK합산단가입력!AD11=입력용!AB16,"블루",IF(SK합산단가입력!AE11=입력용!AB16,"MSC","MSC")) -> 블루 | AD16: =MAX(SK합산단가입력!AG11:AI11) -> 400000 | AE16: =IF(SK합산단가입력!AG11=입력용!AD16,"블루",IF(SK합산단가입력!AH11=입력용!AD16,"MSC","한음")) -> 블루 | AG16: =MAX('KT 합산단가입력'!Y11:AA11) -> 460000 | AH16: =IF('KT 합산단가입력'!Y11=입력용!AG16,"MNS",IF('KT 합산단가입력'!Z11=입력용!AG16,"세이프","이룸")) -> 이룸 | AI16: =MAX('KT 합산단가입력'!AB11:AD11) -> 490000 | AJ16: =IF('KT 합산단가입력'!AB11=입력용!AI16,"MNS",IF('KT 합산단가입력'!AC11=입력용!AI16,"세이프","이룸")) -> 이룸 | AK16: =MAX('KT 합산단가입력'!AF11:AH11) -> 450000 | AL16: =IF('KT 합산단가입력'!AF11=입력용!AK16,"MNS",IF('KT 합산단가입력'!AG11=입력용!AK16,"세이프","이룸")) -> 이룸 | AM16: =MAX('KT 합산단가입력'!AI11:AK11) -> 480000 | AN16: =IF('KT 합산단가입력'!AI11=입력용!AM16,"MNS",IF('KT 합산단가입력'!AJ11=입력용!AM16,"세이프","이룸")) -> 이룸 | AP16: =MAX('LG 합산단가입력'!Z11:AB11) -> 620000 | AQ16: =IF('LG 합산단가입력'!Z11=입력용!AP16,"마라톤",IF('LG 합산단가입력'!AA11=입력용!AP16,"골드","충청")) -> 마라톤 | AR16: =MAX('LG 합산단가입력'!AC11:AE11) -> 610000 | AS16: =IF('LG 합산단가입력'!AC11=입력용!AR16,"마라톤",IF('LG 합산단가입력'!AD11=입력용!AR16,"골드","충청")) -> 마라톤 | AT16: =MAX('LG 합산단가입력'!AG11:AI11) -> 680000 | AU16: =IF('LG 합산단가입력'!AG11=입력용!AT16,"마라톤",IF('LG 합산단가입력'!AH11=입력용!AT16,"골드","충청")) -> 마라톤 | AV16: =MAX('LG 합산단가입력'!AJ11:AL11) -> 670000 | AW16: =IF('LG 합산단가입력'!AJ11=입력용!AV16,"마라톤",IF('LG 합산단가입력'!AK11=입력용!AV16,"골드","충청")) -> 마라톤
C17: 갤럭시 S26+_256G | D17: 1452000 | F17: 190000 | H17: =SUM(D17-F17-G17)-SUM(X17-R17) -> 972000 | I17: =SUM(D17-F17)-SUM(AB17-S17) -> 1032000 | J17: 201000 | L17: =SUM(D17-J17-K17)-SUM(AG17-T17) -> 791000 | M17: =SUM(D17-J17)-SUM(AK17-U17) -> 801000 | N17: 204000 | P17: =SUM(D17-N17-O17)-SUM(AP17-V17) -> 628000 | Q17: =SUM(D17-N17)-SUM(AT17-W17) -> 568000 | R17: 0 | S17: 0 | T17: 0 | U17: 0 | V17: 0 | W17: 0 | X17: =MAX(SK합산단가입력!W12:Y12) -> 290000 | Y17: =IF(SK합산단가입력!W12=입력용!X17,"블루",IF(SK합산단가입력!X12=입력용!X17,"MSC","한음")) -> 블루 | Z17: =MAX(SK합산단가입력!Z12:AB12) -> 510000 | AA17: =IF(SK합산단가입력!Z12=입력용!Z17,"블루",IF(SK합산단가입력!AA12=입력용!Z17,"MSC","한음")) -> 블루 | AB17: =MAX(SK합산단가입력!AD12:AF12) -> 230000 | AC17: =IF(SK합산단가입력!AD12=입력용!AB17,"블루",IF(SK합산단가입력!AE12=입력용!AB17,"MSC","MSC")) -> 블루 | AD17: =MAX(SK합산단가입력!AG12:AI12) -> 400000 | AE17: =IF(SK합산단가입력!AG12=입력용!AD17,"블루",IF(SK합산단가입력!AH12=입력용!AD17,"MSC","한음")) -> 블루 | AG17: =MAX('KT 합산단가입력'!Y12:AA12) -> 460000 | AH17: =IF('KT 합산단가입력'!Y12=입력용!AG17,"MNS",IF('KT 합산단가입력'!Z12=입력용!AG17,"세이프","이룸")) -> 이룸 | AI17: =MAX('KT 합산단가입력'!AB12:AD12) -> 490000 | AJ17: =IF('KT 합산단가입력'!AB12=입력용!AI17,"MNS",IF('KT 합산단가입력'!AC12=입력용!AI17,"세이프","이룸")) -> 이룸 | AK17: =MAX('KT 합산단가입력'!AF12:AH12) -> 450000 | AL17: =IF('KT 합산단가입력'!AF12=입력용!AK17,"MNS",IF('KT 합산단가입력'!AG12=입력용!AK17,"세이프","이룸")) -> 이룸 | AM17: =MAX('KT 합산단가입력'!AI12:AK12) -> 480000 | AN17: =IF('KT 합산단가입력'!AI12=입력용!AM17,"MNS",IF('KT 합산단가입력'!AJ12=입력용!AM17,"세이프","이룸")) -> 이룸 | AP17: =MAX('LG 합산단가입력'!Z12:AB12) -> 620000 | AQ17: =IF('LG 합산단가입력'!Z12=입력용!AP17,"마라톤",IF('LG 합산단가입력'!AA12=입력용!AP17,"골드","충청")) -> 마라톤 | AR17: =MAX('LG 합산단가입력'!AC12:AE12) -> 610000 | AS17: =IF('LG 합산단가입력'!AC12=입력용!AR17,"마라톤",IF('LG 합산단가입력'!AD12=입력용!AR17,"골드","충청")) -> 마라톤 | AT17: =MAX('LG 합산단가입력'!AG12:AI12) -> 680000 | AU17: =IF('LG 합산단가입력'!AG12=입력용!AT17,"마라톤",IF('LG 합산단가입력'!AH12=입력용!AT17,"골드","충청")) -> 마라톤 | AV17: =MAX('LG 합산단가입력'!AJ12:AL12) -> 670000 | AW17: =IF('LG 합산단가입력'!AJ12=입력용!AV17,"마라톤",IF('LG 합산단가입력'!AK12=입력용!AV17,"골드","충청")) -> 마라톤
C18: 갤럭시 S26 울트라_256G | D18: 1797400 | F18: 190000 | H18: =SUM(D18-F18-G18)-SUM(X18-R18) -> 1317400 | I18: =SUM(D18-F18)-SUM(AB18-S18) -> 1377400 | J18: 201000 | L18: =SUM(D18-J18-K18)-SUM(AG18-T18) -> 1176400 | M18: =SUM(D18-J18)-SUM(AK18-U18) -> 1166400 | N18: 204000 | P18: =SUM(D18-N18-O18)-SUM(AP18-V18) -> 973400 | Q18: =SUM(D18-N18)-SUM(AT18-W18) -> 913400 | R18: 0 | S18: 0 | T18: 0 | U18: 0 | V18: 0 | W18: 0 | X18: =MAX(SK합산단가입력!W13:Y13) -> 290000 | Y18: =IF(SK합산단가입력!W13=입력용!X18,"블루",IF(SK합산단가입력!X13=입력용!X18,"MSC","한음")) -> 블루 | Z18: =MAX(SK합산단가입력!Z13:AB13) -> 510000 | AA18: =IF(SK합산단가입력!Z13=입력용!Z18,"블루",IF(SK합산단가입력!AA13=입력용!Z18,"MSC","한음")) -> 블루 | AB18: =MAX(SK합산단가입력!AD13:AF13) -> 230000 | AC18: =IF(SK합산단가입력!AD13=입력용!AB18,"블루",IF(SK합산단가입력!AE13=입력용!AB18,"MSC","MSC")) -> 블루 | AD18: =MAX(SK합산단가입력!AG13:AI13) -> 430000 | AE18: =IF(SK합산단가입력!AG13=입력용!AD18,"블루",IF(SK합산단가입력!AH13=입력용!AD18,"MSC","한음")) -> 블루 | AG18: =MAX('KT 합산단가입력'!Y13:AA13) -> 420000 | AH18: =IF('KT 합산단가입력'!Y13=입력용!AG18,"MNS",IF('KT 합산단가입력'!Z13=입력용!AG18,"세이프","이룸")) -> MNS | AI18: =MAX('KT 합산단가입력'!AB13:AD13) -> 450000 | AJ18: =IF('KT 합산단가입력'!AB13=입력용!AI18,"MNS",IF('KT 합산단가입력'!AC13=입력용!AI18,"세이프","이룸")) -> MNS | AK18: =MAX('KT 합산단가입력'!AF13:AH13) -> 430000 | AL18: =IF('KT 합산단가입력'!AF13=입력용!AK18,"MNS",IF('KT 합산단가입력'!AG13=입력용!AK18,"세이프","이룸")) -> MNS | AM18: =MAX('KT 합산단가입력'!AI13:AK13) -> 460000 | AN18: =IF('KT 합산단가입력'!AI13=입력용!AM18,"MNS",IF('KT 합산단가입력'!AJ13=입력용!AM18,"세이프","이룸")) -> MNS | AP18: =MAX('LG 합산단가입력'!Z13:AB13) -> 620000 | AQ18: =IF('LG 합산단가입력'!Z13=입력용!AP18,"마라톤",IF('LG 합산단가입력'!AA13=입력용!AP18,"골드","충청")) -> 마라톤 | AR18: =MAX('LG 합산단가입력'!AC13:AE13) -> 610000 | AS18: =IF('LG 합산단가입력'!AC13=입력용!AR18,"마라톤",IF('LG 합산단가입력'!AD13=입력용!AR18,"골드","충청")) -> 마라톤 | AT18: =MAX('LG 합산단가입력'!AG13:AI13) -> 680000 | AU18: =IF('LG 합산단가입력'!AG13=입력용!AT18,"마라톤",IF('LG 합산단가입력'!AH13=입력용!AT18,"골드","충청")) -> 마라톤 | AV18: =MAX('LG 합산단가입력'!AJ13:AL13) -> 670000 | AW18: =IF('LG 합산단가입력'!AJ13=입력용!AV18,"마라톤",IF('LG 합산단가입력'!AK13=입력용!AV18,"골드","충청")) -> 마라톤
C19: 갤럭시 S25 | D19: 1155000 | F19: 190000 | H19: =SUM(D19-F19-G19)-SUM(X19-R19) -> 605000 | I19: =SUM(D19-F19)-SUM(AB19-S19) -> 655000 | J19: 201000 | L19: =SUM(D19-J19-K19)-SUM(AG19-T19) -> 514000 | M19: =SUM(D19-J19)-SUM(AK19-U19) -> 624000 | N19: 204000 | P19: =SUM(D19-N19-O19)-SUM(AP19-V19) -> 361000 | Q19: =SUM(D19-N19)-SUM(AT19-W19) -> 321000 | R19: 0 | S19: 0 | T19: 0 | U19: 0 | V19: 0 | W19: 0 | X19: =MAX(SK합산단가입력!W14:Y14) -> 360000 | Y19: =IF(SK합산단가입력!W14=입력용!X19,"블루",IF(SK합산단가입력!X14=입력용!X19,"MSC","한음")) -> MSC | Z19: =MAX(SK합산단가입력!Z14:AB14) -> 410000 | AA19: =IF(SK합산단가입력!Z14=입력용!Z19,"블루",IF(SK합산단가입력!AA14=입력용!Z19,"MSC","한음")) -> MSC | AB19: =MAX(SK합산단가입력!AD14:AF14) -> 310000 | AC19: =IF(SK합산단가입력!AD14=입력용!AB19,"블루",IF(SK합산단가입력!AE14=입력용!AB19,"MSC","MSC")) -> MSC | AD19: =MAX(SK합산단가입력!AG14:AI14) -> 360000 | AE19: =IF(SK합산단가입력!AG14=입력용!AD19,"블루",IF(SK합산단가입력!AH14=입력용!AD19,"MSC","한음")) -> MSC | AF19: =C19 -> 갤럭시 S25 | AG19: =MAX('KT 합산단가입력'!Y14:AA14) -> 440000 | AH19: =IF('KT 합산단가입력'!Y14=입력용!AG19,"MNS",IF('KT 합산단가입력'!Z14=입력용!AG19,"세이프","이룸")) -> MNS | AI19: =MAX('KT 합산단가입력'!AB14:AD14) -> 470000 | AJ19: =IF('KT 합산단가입력'!AB14=입력용!AI19,"MNS",IF('KT 합산단가입력'!AC14=입력용!AI19,"세이프","이룸")) -> MNS | AK19: =MAX('KT 합산단가입력'!AF14:AH14) -> 330000 | AL19: =IF('KT 합산단가입력'!AF14=입력용!AK19,"MNS",IF('KT 합산단가입력'!AG14=입력용!AK19,"세이프","이룸")) -> 이룸 | AM19: =MAX('KT 합산단가입력'!AI14:AK14) -> 360000 | AN19: =IF('KT 합산단가입력'!AI14=입력용!AM19,"MNS",IF('KT 합산단가입력'!AJ14=입력용!AM19,"세이프","이룸")) -> 이룸 | AO19: =C19 -> 갤럭시 S25 | AP19: =MAX('LG 합산단가입력'!Z14:AB14) -> 590000 | AQ19: =IF('LG 합산단가입력'!Z14=입력용!AP19,"마라톤",IF('LG 합산단가입력'!AA14=입력용!AP19,"골드","충청")) -> 충청 | AR19: =MAX('LG 합산단가입력'!AC14:AE14) -> 590000 | AS19: =IF('LG 합산단가입력'!AC14=입력용!AR19,"마라톤",IF('LG 합산단가입력'!AD14=입력용!AR19,"골드","충청")) -> 충청 | AT19: =MAX('LG 합산단가입력'!AG14:AI14) -> 630000 | AU19: =IF('LG 합산단가입력'!AG14=입력용!AT19,"마라톤",IF('LG 합산단가입력'!AH14=입력용!AT19,"골드","충청")) -> 충청 | AV19: =MAX('LG 합산단가입력'!AJ14:AL14) -> 630000 | AW19: =IF('LG 합산단가입력'!AJ14=입력용!AV19,"마라톤",IF('LG 합산단가입력'!AK14=입력용!AV19,"골드","충청")) -> 충청
C20: 갤럭시 S25+ | D20: 1353000 | F20: 190000 | H20: =SUM(D20-F20-G20)-SUM(X20-R20) -> 943000 | I20: =SUM(D20-F20)-SUM(AB20-S20) -> 1003000 | J20: 201000 | L20: =SUM(D20-J20-K20)-SUM(AG20-T20) -> 1072000 | M20: =SUM(D20-J20)-SUM(AK20-U20) -> 1072000 | N20: 204000 | P20: =SUM(D20-N20-O20)-SUM(AP20-V20) -> 1039000 | Q20: =SUM(D20-N20)-SUM(AT20-W20) -> 1039000 | R20: 0 | S20: 0 | T20: 0 | U20: 0 | V20: 0 | W20: 0 | X20: =MAX(SK합산단가입력!W15:Y15) -> 220000 | Y20: =IF(SK합산단가입력!W15=입력용!X20,"블루",IF(SK합산단가입력!X15=입력용!X20,"MSC","한음")) -> 블루 | Z20: =MAX(SK합산단가입력!Z15:AB15) -> 270000 | AA20: =IF(SK합산단가입력!Z15=입력용!Z20,"블루",IF(SK합산단가입력!AA15=입력용!Z20,"MSC","한음")) -> 블루 | AB20: =MAX(SK합산단가입력!AD15:AF15) -> 160000 | AC20: =IF(SK합산단가입력!AD15=입력용!AB20,"블루",IF(SK합산단가입력!AE15=입력용!AB20,"MSC","MSC")) -> 블루 | AD20: =MAX(SK합산단가입력!AG15:AI15) -> 210000 | AE20: =IF(SK합산단가입력!AG15=입력용!AD20,"블루",IF(SK합산단가입력!AH15=입력용!AD20,"MSC","한음")) -> 블루 | AF20: =C20 -> 갤럭시 S25+ | AG20: =MAX('KT 합산단가입력'!Y15:AA15) -> 80000 | AH20: =IF('KT 합산단가입력'!Y15=입력용!AG20,"MNS",IF('KT 합산단가입력'!Z15=입력용!AG20,"세이프","이룸")) -> 세이프 | AI20: =MAX('KT 합산단가입력'!AB15:AD15) -> 80000 | AJ20: =IF('KT 합산단가입력'!AB15=입력용!AI20,"MNS",IF('KT 합산단가입력'!AC15=입력용!AI20,"세이프","이룸")) -> 세이프 | AK20: =MAX('KT 합산단가입력'!AF15:AH15) -> 80000 | AL20: =IF('KT 합산단가입력'!AF15=입력용!AK20,"MNS",IF('KT 합산단가입력'!AG15=입력용!AK20,"세이프","이룸")) -> 세이프 | AM20: =MAX('KT 합산단가입력'!AI15:AK15) -> 80000 | AN20: =IF('KT 합산단가입력'!AI15=입력용!AM20,"MNS",IF('KT 합산단가입력'!AJ15=입력용!AM20,"세이프","이룸")) -> 세이프 | AO20: =C20 -> 갤럭시 S25+ | AP20: =MAX('LG 합산단가입력'!Z15:AB15) -> 110000 | AQ20: =IF('LG 합산단가입력'!Z15=입력용!AP20,"마라톤",IF('LG 합산단가입력'!AA15=입력용!AP20,"골드","충청")) -> 마라톤 | AR20: =MAX('LG 합산단가입력'!AC15:AE15) -> 100000 | AS20: =IF('LG 합산단가입력'!AC15=입력용!AR20,"마라톤",IF('LG 합산단가입력'!AD15=입력용!AR20,"골드","충청")) -> 마라톤 | AT20: =MAX('LG 합산단가입력'!AG15:AI15) -> 110000 | AU20: =IF('LG 합산단가입력'!AG15=입력용!AT20,"마라톤",IF('LG 합산단가입력'!AH15=입력용!AT20,"골드","충청")) -> 골드 | AV20: =MAX('LG 합산단가입력'!AJ15:AL15) -> 100000 | AW20: =IF('LG 합산단가입력'!AJ15=입력용!AV20,"마라톤",IF('LG 합산단가입력'!AK15=입력용!AV20,"골드","충청")) -> 골드
C21: 갤럭시 S25 울트라 | D21: 1698400 | F21: 190000 | H21: =SUM(D21-F21-G21)-SUM(X21-R21) -> 1148400 | I21: =SUM(D21-F21)-SUM(AB21-S21) -> 1198400 | J21: 201000 | L21: =SUM(D21-J21-K21)-SUM(AG21-T21) -> 1057400 | M21: =SUM(D21-J21)-SUM(AK21-U21) -> 1167400 | N21: 204000 | P21: =SUM(D21-N21-O21)-SUM(AP21-V21) -> 944400 | Q21: =SUM(D21-N21)-SUM(AT21-W21) -> 1074400 | R21: 0 | S21: 0 | T21: 0 | U21: 0 | V21: 0 | W21: 0 | X21: =MAX(SK합산단가입력!W16:Y16) -> 360000 | Y21: =IF(SK합산단가입력!W16=입력용!X21,"블루",IF(SK합산단가입력!X16=입력용!X21,"MSC","한음")) -> MSC | Z21: =MAX(SK합산단가입력!Z16:AB16) -> 410000 | AA21: =IF(SK합산단가입력!Z16=입력용!Z21,"블루",IF(SK합산단가입력!AA16=입력용!Z21,"MSC","한음")) -> MSC | AB21: =MAX(SK합산단가입력!AD16:AF16) -> 310000 | AC21: =IF(SK합산단가입력!AD16=입력용!AB21,"블루",IF(SK합산단가입력!AE16=입력용!AB21,"MSC","MSC")) -> MSC | AD21: =MAX(SK합산단가입력!AG16:AI16) -> 360000 | AE21: =IF(SK합산단가입력!AG16=입력용!AD21,"블루",IF(SK합산단가입력!AH16=입력용!AD21,"MSC","한음")) -> MSC | AF21: =C21 -> 갤럭시 S25 울트라 | AG21: =MAX('KT 합산단가입력'!Y16:AA16) -> 440000 | AH21: =IF('KT 합산단가입력'!Y16=입력용!AG21,"MNS",IF('KT 합산단가입력'!Z16=입력용!AG21,"세이프","이룸")) -> MNS | AI21: =MAX('KT 합산단가입력'!AB16:AD16) -> 470000 | AJ21: =IF('KT 합산단가입력'!AB16=입력용!AI21,"MNS",IF('KT 합산단가입력'!AC16=입력용!AI21,"세이프","이룸")) -> MNS | AK21: =MAX('KT 합산단가입력'!AF16:AH16) -> 330000 | AL21: =IF('KT 합산단가입력'!AF16=입력용!AK21,"MNS",IF('KT 합산단가입력'!AG16=입력용!AK21,"세이프","이룸")) -> 이룸 | AM21: =MAX('KT 합산단가입력'!AI16:AK16) -> 360000 | AN21: =IF('KT 합산단가입력'!AI16=입력용!AM21,"MNS",IF('KT 합산단가입력'!AJ16=입력용!AM21,"세이프","이룸")) -> 이룸 | AO21: =C21 -> 갤럭시 S25 울트라 | AP21: =MAX('LG 합산단가입력'!Z16:AB16) -> 550000 | AQ21: =IF('LG 합산단가입력'!Z16=입력용!AP21,"마라톤",IF('LG 합산단가입력'!AA16=입력용!AP21,"골드","충청")) -> 마라톤 | AR21: =MAX('LG 합산단가입력'!AC16:AE16) -> 540000 | AS21: =IF('LG 합산단가입력'!AC16=입력용!AR21,"마라톤",IF('LG 합산단가입력'!AD16=입력용!AR21,"골드","충청")) -> 마라톤 | AT21: =MAX('LG 합산단가입력'!AG16:AI16) -> 420000 | AU21: =IF('LG 합산단가입력'!AG16=입력용!AT21,"마라톤",IF('LG 합산단가입력'!AH16=입력용!AT21,"골드","충청")) -> 마라톤 | AV21: =MAX('LG 합산단가입력'!AJ16:AL16) -> 410000 | AW21: =IF('LG 합산단가입력'!AJ16=입력용!AV21,"마라톤",IF('LG 합산단가입력'!AK16=입력용!AV21,"골드","충청")) -> 마라톤
C22: 갤럭시 S25 엣지 | D22: 1496000 | F22: 600000 | H22: =SUM(D22-F22-G22)-SUM(X22-R22) -> 426000 | I22: =SUM(D22-F22)-SUM(AB22-S22) -> 476000 | J22: 600000 | L22: =SUM(D22-J22-K22)-SUM(AG22-T22) -> 376000 | M22: =SUM(D22-J22)-SUM(AK22-U22) -> 296000 | N22: 600000 | P22: =SUM(D22-N22-O22)-SUM(AP22-V22) -> 246000 | Q22: =SUM(D22-N22)-SUM(AT22-W22) -> 206000 | R22: 0 | S22: 0 | T22: 0 | U22: 0 | V22: 0 | W22: 0 | X22: =MAX(SK합산단가입력!W17:Y17) -> 470000 | Y22: =IF(SK합산단가입력!W17=입력용!X22,"블루",IF(SK합산단가입력!X17=입력용!X22,"MSC","한음")) -> MSC | Z22: =MAX(SK합산단가입력!Z17:AB17) -> 300000 | AA22: =IF(SK합산단가입력!Z17=입력용!Z22,"블루",IF(SK합산단가입력!AA17=입력용!Z22,"MSC","한음")) -> 블루 | AB22: =MAX(SK합산단가입력!AD17:AF17) -> 420000 | AC22: =IF(SK합산단가입력!AD17=입력용!AB22,"블루",IF(SK합산단가입력!AE17=입력용!AB22,"MSC","MSC")) -> MSC | AD22: =MAX(SK합산단가입력!AG17:AI17) -> 240000 | AE22: =IF(SK합산단가입력!AG17=입력용!AD22,"블루",IF(SK합산단가입력!AH17=입력용!AD22,"MSC","한음")) -> 블루 | AF22: =C22 -> 갤럭시 S25 엣지 | AG22: =MAX('KT 합산단가입력'!Y17:AA17) -> 520000 | AH22: =IF('KT 합산단가입력'!Y17=입력용!AG22,"MNS",IF('KT 합산단가입력'!Z17=입력용!AG22,"세이프","이룸")) -> 이룸 | AI22: =MAX('KT 합산단가입력'!AB17:AD17) -> 550000 | AJ22: =IF('KT 합산단가입력'!AB17=입력용!AI22,"MNS",IF('KT 합산단가입력'!AC17=입력용!AI22,"세이프","이룸")) -> 이룸 | AK22: =MAX('KT 합산단가입력'!AF17:AH17) -> 600000 | AL22: =IF('KT 합산단가입력'!AF17=입력용!AK22,"MNS",IF('KT 합산단가입력'!AG17=입력용!AK22,"세이프","이룸")) -> MNS | AM22: =MAX('KT 합산단가입력'!AI17:AK17) -> 630000 | AN22: =IF('KT 합산단가입력'!AI17=입력용!AM22,"MNS",IF('KT 합산단가입력'!AJ17=입력용!AM22,"세이프","이룸")) -> MNS | AO22: =C22 -> 갤럭시 S25 엣지 | AP22: =MAX('LG 합산단가입력'!Z17:AB17) -> 650000 | AQ22: =IF('LG 합산단가입력'!Z17=입력용!AP22,"마라톤",IF('LG 합산단가입력'!AA17=입력용!AP22,"골드","충청")) -> 충청 | AR22: =MAX('LG 합산단가입력'!AC17:AE17) -> 650000 | AS22: =IF('LG 합산단가입력'!AC17=입력용!AR22,"마라톤",IF('LG 합산단가입력'!AD17=입력용!AR22,"골드","충청")) -> 충청 | AT22: =MAX('LG 합산단가입력'!AG17:AI17) -> 690000 | AU22: =IF('LG 합산단가입력'!AG17=입력용!AT22,"마라톤",IF('LG 합산단가입력'!AH17=입력용!AT22,"골드","충청")) -> 충청 | AV22: =MAX('LG 합산단가입력'!AJ17:AL17) -> 690000 | AW22: =IF('LG 합산단가입력'!AJ17=입력용!AV22,"마라톤",IF('LG 합산단가입력'!AK17=입력용!AV22,"골드","충청")) -> 충청
C23: 아이폰17 256G | D23: 1287000 | F23: 450000 | H23: =SUM(D23-F23-G23)-SUM(X23-R23) -> 267000 | I23: =SUM(D23-F23)-SUM(AB23-S23) -> 537000 | J23: 450000 | K23: 50000 | L23: =SUM(D23-J23-K23)-SUM(AG23-T23) -> 117000 | M23: =SUM(D23-J23)-SUM(AK23-U23) -> 527000 | N23: 450000 | O23: 100000 | P23: =SUM(D23-N23-O23)-SUM(AP23-V23) -> -53000 | Q23: =SUM(D23-N23)-SUM(AT23-W23) -> 367000 | R23: 0 | S23: 0 | T23: 0 | U23: 0 | V23: 0 | W23: 0 | X23: =MAX(SK합산단가입력!W18:Y18) -> 570000 | Y23: =IF(SK합산단가입력!W18=입력용!X23,"블루",IF(SK합산단가입력!X18=입력용!X23,"MSC","한음")) -> 블루 | Z23: =MAX(SK합산단가입력!Z18:AB18) -> 520000 | AA23: =IF(SK합산단가입력!Z18=입력용!Z23,"블루",IF(SK합산단가입력!AA18=입력용!Z23,"MSC","한음")) -> 블루 | AB23: =MAX(SK합산단가입력!AD18:AF18) -> 300000 | AC23: =IF(SK합산단가입력!AD18=입력용!AB23,"블루",IF(SK합산단가입력!AE18=입력용!AB23,"MSC","MSC")) -> 블루 | AD23: =MAX(SK합산단가입력!AG18:AI18) -> 250000 | AE23: =IF(SK합산단가입력!AG18=입력용!AD23,"블루",IF(SK합산단가입력!AH18=입력용!AD23,"MSC","한음")) -> 블루 | AF23: =C23 -> 아이폰17 256G | AG23: =MAX('KT 합산단가입력'!Y18:AA18) -> 670000 | AH23: =IF('KT 합산단가입력'!Y18=입력용!AG23,"MNS",IF('KT 합산단가입력'!Z18=입력용!AG23,"세이프","이룸")) -> MNS | AI23: =MAX('KT 합산단가입력'!AB18:AD18) -> 700000 | AJ23: =IF('KT 합산단가입력'!AB18=입력용!AI23,"MNS",IF('KT 합산단가입력'!AC18=입력용!AI23,"세이프","이룸")) -> MNS | AK23: =MAX('KT 합산단가입력'!AF18:AH18) -> 310000 | AL23: =IF('KT 합산단가입력'!AF18=입력용!AK23,"MNS",IF('KT 합산단가입력'!AG18=입력용!AK23,"세이프","이룸")) -> 이룸 | AM23: =MAX('KT 합산단가입력'!AI18:AK18) -> 340000 | AN23: =IF('KT 합산단가입력'!AI18=입력용!AM23,"MNS",IF('KT 합산단가입력'!AJ18=입력용!AM23,"세이프","이룸")) -> 이룸 | AO23: =C23 -> 아이폰17 256G | AP23: =MAX('LG 합산단가입력'!Z18:AB18) -> 790000 | AQ23: =IF('LG 합산단가입력'!Z18=입력용!AP23,"마라톤",IF('LG 합산단가입력'!AA18=입력용!AP23,"골드","충청")) -> 마라톤 | AR23: =MAX('LG 합산단가입력'!AC18:AE18) -> 780000 | AS23: =IF('LG 합산단가입력'!AC18=입력용!AR23,"마라톤",IF('LG 합산단가입력'!AD18=입력용!AR23,"골드","충청")) -> 마라톤 | AT23: =MAX('LG 합산단가입력'!AG18:AI18) -> 470000 | AU23: =IF('LG 합산단가입력'!AG18=입력용!AT23,"마라톤",IF('LG 합산단가입력'!AH18=입력용!AT23,"골드","충청")) -> 마라톤 | AV23: =MAX('LG 합산단가입력'!AJ18:AL18) -> 470000 | AW23: =IF('LG 합산단가입력'!AJ18=입력용!AV23,"마라톤",IF('LG 합산단가입력'!AK18=입력용!AV23,"골드","충청")) -> 충청
C24: 아이폰17 에어 256G | D24: 1584000 | F24: 450000 | H24: =SUM(D24-F24-G24)-SUM(X24-R24) -> 534000 | I24: =SUM(D24-F24)-SUM(AB24-S24) -> 834000 | J24: 450000 | L24: =SUM(D24-J24-K24)-SUM(AG24-T24) -> 464000 | M24: =SUM(D24-J24)-SUM(AK24-U24) -> 824000 | N24: 450000 | O24: 100000 | P24: =SUM(D24-N24-O24)-SUM(AP24-V24) -> 244000 | Q24: =SUM(D24-N24)-SUM(AT24-W24) -> 664000 | R24: 0 | S24: 0 | T24: 0 | U24: 0 | V24: 0 | W24: 0 | X24: =MAX(SK합산단가입력!W19:Y19) -> 600000 | Y24: =IF(SK합산단가입력!W19=입력용!X24,"블루",IF(SK합산단가입력!X19=입력용!X24,"MSC","한음")) -> 블루 | Z24: =MAX(SK합산단가입력!Z19:AB19) -> 550000 | AA24: =IF(SK합산단가입력!Z19=입력용!Z24,"블루",IF(SK합산단가입력!AA19=입력용!Z24,"MSC","한음")) -> 블루 | AB24: =MAX(SK합산단가입력!AD19:AF19) -> 300000 | AC24: =IF(SK합산단가입력!AD19=입력용!AB24,"블루",IF(SK합산단가입력!AE19=입력용!AB24,"MSC","MSC")) -> 블루 | AD24: =MAX(SK합산단가입력!AG19:AI19) -> 250000 | AE24: =IF(SK합산단가입력!AG19=입력용!AD24,"블루",IF(SK합산단가입력!AH19=입력용!AD24,"MSC","한음")) -> 블루 | AF24: =C24 -> 아이폰17 에어 256G | AG24: =MAX('KT 합산단가입력'!Y19:AA19) -> 670000 | AH24: =IF('KT 합산단가입력'!Y19=입력용!AG24,"MNS",IF('KT 합산단가입력'!Z19=입력용!AG24,"세이프","이룸")) -> MNS | AI24: =MAX('KT 합산단가입력'!AB19:AD19) -> 700000 | AJ24: =IF('KT 합산단가입력'!AB19=입력용!AI24,"MNS",IF('KT 합산단가입력'!AC19=입력용!AI24,"세이프","이룸")) -> MNS | AK24: =MAX('KT 합산단가입력'!AF19:AH19) -> 310000 | AL24: =IF('KT 합산단가입력'!AF19=입력용!AK24,"MNS",IF('KT 합산단가입력'!AG19=입력용!AK24,"세이프","이룸")) -> 이룸 | AM24: =MAX('KT 합산단가입력'!AI19:AK19) -> 340000 | AN24: =IF('KT 합산단가입력'!AI19=입력용!AM24,"MNS",IF('KT 합산단가입력'!AJ19=입력용!AM24,"세이프","이룸")) -> 이룸 | AO24: =C24 -> 아이폰17 에어 256G | AP24: =MAX('LG 합산단가입력'!Z19:AB19) -> 790000 | AQ24: =IF('LG 합산단가입력'!Z19=입력용!AP24,"마라톤",IF('LG 합산단가입력'!AA19=입력용!AP24,"골드","충청")) -> 마라톤 | AR24: =MAX('LG 합산단가입력'!AC19:AE19) -> 780000 | AS24: =IF('LG 합산단가입력'!AC19=입력용!AR24,"마라톤",IF('LG 합산단가입력'!AD19=입력용!AR24,"골드","충청")) -> 마라톤 | AT24: =MAX('LG 합산단가입력'!AG19:AI19) -> 470000 | AU24: =IF('LG 합산단가입력'!AG19=입력용!AT24,"마라톤",IF('LG 합산단가입력'!AH19=입력용!AT24,"골드","충청")) -> 마라톤 | AV24: =MAX('LG 합산단가입력'!AJ19:AL19) -> 470000 | AW24: =IF('LG 합산단가입력'!AJ19=입력용!AV24,"마라톤",IF('LG 합산단가입력'!AK19=입력용!AV24,"골드","충청")) -> 충청
C25: 아이폰17 프로 256G | D25: 1782000 | F25: 450000 | H25: =SUM(D25-F25-G25)-SUM(X25-R25) -> 812000 | I25: =SUM(D25-F25)-SUM(AB25-S25) -> 1032000 | J25: 450000 | L25: =SUM(D25-J25-K25)-SUM(AG25-T25) -> 662000 | M25: =SUM(D25-J25)-SUM(AK25-U25) -> 1022000 | N25: 450000 | O25: 100000 | P25: =SUM(D25-N25-O25)-SUM(AP25-V25) -> 492000 | Q25: =SUM(D25-N25)-SUM(AT25-W25) -> 902000 | R25: 0 | S25: 0 | T25: 0 | U25: 0 | V25: 0 | W25: 0 | X25: =MAX(SK합산단가입력!W20:Y20) -> 520000 | Y25: =IF(SK합산단가입력!W20=입력용!X25,"블루",IF(SK합산단가입력!X20=입력용!X25,"MSC","한음")) -> MSC | Z25: =MAX(SK합산단가입력!Z20:AB20) -> 470000 | AA25: =IF(SK합산단가입력!Z20=입력용!Z25,"블루",IF(SK합산단가입력!AA20=입력용!Z25,"MSC","한음")) -> MSC | AB25: =MAX(SK합산단가입력!AD20:AF20) -> 300000 | AC25: =IF(SK합산단가입력!AD20=입력용!AB25,"블루",IF(SK합산단가입력!AE20=입력용!AB25,"MSC","MSC")) -> 블루 | AD25: =MAX(SK합산단가입력!AG20:AI20) -> 250000 | AE25: =IF(SK합산단가입력!AG20=입력용!AD25,"블루",IF(SK합산단가입력!AH20=입력용!AD25,"MSC","한음")) -> 블루 | AF25: =C25 -> 아이폰17 프로 256G | AG25: =MAX('KT 합산단가입력'!Y20:AA20) -> 670000 | AH25: =IF('KT 합산단가입력'!Y20=입력용!AG25,"MNS",IF('KT 합산단가입력'!Z20=입력용!AG25,"세이프","이룸")) -> MNS | AI25: =MAX('KT 합산단가입력'!AB20:AD20) -> 700000 | AJ25: =IF('KT 합산단가입력'!AB20=입력용!AI25,"MNS",IF('KT 합산단가입력'!AC20=입력용!AI25,"세이프","이룸")) -> MNS | AK25: =MAX('KT 합산단가입력'!AF20:AH20) -> 310000 | AL25: =IF('KT 합산단가입력'!AF20=입력용!AK25,"MNS",IF('KT 합산단가입력'!AG20=입력용!AK25,"세이프","이룸")) -> 이룸 | AM25: =MAX('KT 합산단가입력'!AI20:AK20) -> 340000 | AN25: =IF('KT 합산단가입력'!AI20=입력용!AM25,"MNS",IF('KT 합산단가입력'!AJ20=입력용!AM25,"세이프","이룸")) -> 이룸 | AO25: =C25 -> 아이폰17 프로 256G | AP25: =MAX('LG 합산단가입력'!Z20:AB20) -> 740000 | AQ25: =IF('LG 합산단가입력'!Z20=입력용!AP25,"마라톤",IF('LG 합산단가입력'!AA20=입력용!AP25,"골드","충청")) -> 골드 | AR25: =MAX('LG 합산단가입력'!AC20:AE20) -> 730000 | AS25: =IF('LG 합산단가입력'!AC20=입력용!AR25,"마라톤",IF('LG 합산단가입력'!AD20=입력용!AR25,"골드","충청")) -> 골드 | AT25: =MAX('LG 합산단가입력'!AG20:AI20) -> 430000 | AU25: =IF('LG 합산단가입력'!AG20=입력용!AT25,"마라톤",IF('LG 합산단가입력'!AH20=입력용!AT25,"골드","충청")) -> 마라톤 | AV25: =MAX('LG 합산단가입력'!AJ20:AL20) -> 420000 | AW25: =IF('LG 합산단가입력'!AJ20=입력용!AV25,"마라톤",IF('LG 합산단가입력'!AK20=입력용!AV25,"골드","충청")) -> 마라톤
C26: 아이폰17 프로맥스 256G | D26: 1980000 | F26: 220000 | H26: =SUM(D26-F26-G26)-SUM(X26-R26) -> 1490000 | I26: =SUM(D26-F26)-SUM(AB26-S26) -> 1460000 | J26: 201000 | L26: =SUM(D26-J26-K26)-SUM(AG26-T26) -> 1169000 | M26: =SUM(D26-J26)-SUM(AK26-U26) -> 1519000 | N26: 204000 | P26: =SUM(D26-N26-O26)-SUM(AP26-V26) -> 1056000 | Q26: =SUM(D26-N26)-SUM(AT26-W26) -> 1346000 | R26: 0 | S26: 0 | T26: 0 | U26: 0 | V26: 0 | W26: 0 | X26: =MAX(SK합산단가입력!W21:Y21) -> 270000 | Y26: =IF(SK합산단가입력!W21=입력용!X26,"블루",IF(SK합산단가입력!X21=입력용!X26,"MSC","한음")) -> MSC | Z26: =MAX(SK합산단가입력!Z21:AB21) -> 520000 | AA26: =IF(SK합산단가입력!Z21=입력용!Z26,"블루",IF(SK합산단가입력!AA21=입력용!Z26,"MSC","한음")) -> MSC | AB26: =MAX(SK합산단가입력!AD21:AF21) -> 300000 | AC26: =IF(SK합산단가입력!AD21=입력용!AB26,"블루",IF(SK합산단가입력!AE21=입력용!AB26,"MSC","MSC")) -> 블루 | AD26: =MAX(SK합산단가입력!AG21:AI21) -> 250000 | AE26: =IF(SK합산단가입력!AG21=입력용!AD26,"블루",IF(SK합산단가입력!AH21=입력용!AD26,"MSC","한음")) -> 블루 | AF26: =C26 -> 아이폰17 프로맥스 256G | AG26: =MAX('KT 합산단가입력'!Y21:AA21) -> 610000 | AH26: =IF('KT 합산단가입력'!Y21=입력용!AG26,"MNS",IF('KT 합산단가입력'!Z21=입력용!AG26,"세이프","이룸")) -> MNS | AI26: =MAX('KT 합산단가입력'!AB21:AD21) -> 640000 | AJ26: =IF('KT 합산단가입력'!AB21=입력용!AI26,"MNS",IF('KT 합산단가입력'!AC21=입력용!AI26,"세이프","이룸")) -> MNS | AK26: =MAX('KT 합산단가입력'!AF21:AH21) -> 260000 | AL26: =IF('KT 합산단가입력'!AF21=입력용!AK26,"MNS",IF('KT 합산단가입력'!AG21=입력용!AK26,"세이프","이룸")) -> 이룸 | AM26: =MAX('KT 합산단가입력'!AI21:AK21) -> 290000 | AN26: =IF('KT 합산단가입력'!AI21=입력용!AM26,"MNS",IF('KT 합산단가입력'!AJ21=입력용!AM26,"세이프","이룸")) -> 이룸 | AO26: =C26 -> 아이폰17 프로맥스 256G | AP26: =MAX('LG 합산단가입력'!Z21:AB21) -> 720000 | AQ26: =IF('LG 합산단가입력'!Z21=입력용!AP26,"마라톤",IF('LG 합산단가입력'!AA21=입력용!AP26,"골드","충청")) -> 마라톤 | AR26: =MAX('LG 합산단가입력'!AC21:AE21) -> 710000 | AS26: =IF('LG 합산단가입력'!AC21=입력용!AR26,"마라톤",IF('LG 합산단가입력'!AD21=입력용!AR26,"골드","충청")) -> 마라톤 | AT26: =MAX('LG 합산단가입력'!AG21:AI21) -> 430000 | AU26: =IF('LG 합산단가입력'!AG21=입력용!AT26,"마라톤",IF('LG 합산단가입력'!AH21=입력용!AT26,"골드","충청")) -> 마라톤 | AV26: =MAX('LG 합산단가입력'!AJ21:AL21) -> 420000 | AW26: =IF('LG 합산단가입력'!AJ21=입력용!AV26,"마라톤",IF('LG 합산단가입력'!AK21=입력용!AV26,"골드","충청")) -> 마라톤
C27: 아이폰16 128G | D27: 1243000 | F27: 220000 | H27: =SUM(D27-F27-G27)-SUM(X27-R27) -> 1023000 | I27: =SUM(D27-F27)-SUM(AB27-S27) -> 1023000 | J27: 550000 | K27: 150000 | L27: =SUM(D27-J27-K27)-SUM(AG27-T27) -> 463000 | M27: =SUM(D27-J27)-SUM(AK27-U27) -> 613000 | N27: 450000 | P27: =SUM(D27-N27-O27)-SUM(AP27-V27) -> 683000 | Q27: =SUM(D27-N27)-SUM(AT27-W27) -> 793000 | R27: 0 | S27: 0 | T27: 0 | U27: 0 | V27: 0 | W27: 0 | X27: =MAX(SK합산단가입력!W22:Y22) -> 0 | Y27: =IF(SK합산단가입력!W22=입력용!X27,"블루",IF(SK합산단가입력!X22=입력용!X27,"MSC","한음")) -> MSC | Z27: =MAX(SK합산단가입력!Z22:AB22) -> 20000 | AA27: =IF(SK합산단가입력!Z22=입력용!Z27,"블루",IF(SK합산단가입력!AA22=입력용!Z27,"MSC","한음")) -> 블루 | AB27: =MAX(SK합산단가입력!AD22:AF22) -> 0 | AC27: =IF(SK합산단가입력!AD22=입력용!AB27,"블루",IF(SK합산단가입력!AE22=입력용!AB27,"MSC","MSC")) -> MSC | AD27: =MAX(SK합산단가입력!AG22:AI22) -> 0 | AE27: =IF(SK합산단가입력!AG22=입력용!AD27,"블루",IF(SK합산단가입력!AH22=입력용!AD27,"MSC","한음")) -> MSC | AF27: =C27 -> 아이폰16 128G | AG27: =MAX('KT 합산단가입력'!Y22:AA22) -> 80000 | AH27: =IF('KT 합산단가입력'!Y22=입력용!AG27,"MNS",IF('KT 합산단가입력'!Z22=입력용!AG27,"세이프","이룸")) -> 세이프 | AI27: =MAX('KT 합산단가입력'!AB22:AD22) -> 80000 | AJ27: =IF('KT 합산단가입력'!AB22=입력용!AI27,"MNS",IF('KT 합산단가입력'!AC22=입력용!AI27,"세이프","이룸")) -> 세이프 | AK27: =MAX('KT 합산단가입력'!AF22:AH22) -> 80000 | AL27: =IF('KT 합산단가입력'!AF22=입력용!AK27,"MNS",IF('KT 합산단가입력'!AG22=입력용!AK27,"세이프","이룸")) -> 세이프 | AM27: =MAX('KT 합산단가입력'!AI22:AK22) -> 80000 | AN27: =IF('KT 합산단가입력'!AI22=입력용!AM27,"MNS",IF('KT 합산단가입력'!AJ22=입력용!AM27,"세이프","이룸")) -> 세이프 | AO27: =C27 -> 아이폰16 128G | AP27: =MAX('LG 합산단가입력'!Z22:AB22) -> 110000 | AQ27: =IF('LG 합산단가입력'!Z22=입력용!AP27,"마라톤",IF('LG 합산단가입력'!AA22=입력용!AP27,"골드","충청")) -> 마라톤 | AR27: =MAX('LG 합산단가입력'!AC22:AE22) -> 40000 | AS27: =IF('LG 합산단가입력'!AC22=입력용!AR27,"마라톤",IF('LG 합산단가입력'!AD22=입력용!AR27,"골드","충청")) -> 마라톤 | AT27: =MAX('LG 합산단가입력'!AG22:AI22) -> 0 | AU27: =IF('LG 합산단가입력'!AG22=입력용!AT27,"마라톤",IF('LG 합산단가입력'!AH22=입력용!AT27,"골드","충청")) -> 마라톤 | AV27: =MAX('LG 합산단가입력'!AJ22:AL22) -> 0 | AW27: =IF('LG 합산단가입력'!AJ22=입력용!AV27,"마라톤",IF('LG 합산단가입력'!AK22=입력용!AV27,"골드","충청")) -> 충청
C28: 아이폰16+ 128G | D28: 1342000 | F28: 220000 | H28: =SUM(D28-F28-G28)-SUM(X28-R28) -> 1122000 | I28: =SUM(D28-F28)-SUM(AB28-S28) -> 1122000 | J28: 550000 | L28: =SUM(D28-J28-K28)-SUM(AG28-T28) -> 712000 | M28: =SUM(D28-J28)-SUM(AK28-U28) -> 792000 | N28: 204000 | P28: =SUM(D28-N28-O28)-SUM(AP28-V28) -> 1048000 | Q28: =SUM(D28-N28)-SUM(AT28-W28) -> 1138000 | R28: 0 | S28: 0 | T28: 0 | U28: 0 | V28: 0 | W28: 0 | X28: =MAX(SK합산단가입력!W23:Y23) -> 0 | Y28: =IF(SK합산단가입력!W23=입력용!X28,"블루",IF(SK합산단가입력!X23=입력용!X28,"MSC","한음")) -> MSC | Z28: =MAX(SK합산단가입력!Z23:AB23) -> 20000 | AA28: =IF(SK합산단가입력!Z23=입력용!Z28,"블루",IF(SK합산단가입력!AA23=입력용!Z28,"MSC","한음")) -> 블루 | AB28: =MAX(SK합산단가입력!AD23:AF23) -> 0 | AC28: =IF(SK합산단가입력!AD23=입력용!AB28,"블루",IF(SK합산단가입력!AE23=입력용!AB28,"MSC","MSC")) -> MSC | AD28: =MAX(SK합산단가입력!AG23:AI23) -> 0 | AE28: =IF(SK합산단가입력!AG23=입력용!AD28,"블루",IF(SK합산단가입력!AH23=입력용!AD28,"MSC","한음")) -> MSC | AF28: =C28 -> 아이폰16+ 128G | AG28: =MAX('KT 합산단가입력'!Y23:AA23) -> 80000 | AH28: =IF('KT 합산단가입력'!Y23=입력용!AG28,"MNS",IF('KT 합산단가입력'!Z23=입력용!AG28,"세이프","이룸")) -> 세이프 | AI28: =MAX('KT 합산단가입력'!AB23:AD23) -> 80000 | AJ28: =IF('KT 합산단가입력'!AB23=입력용!AI28,"MNS",IF('KT 합산단가입력'!AC23=입력용!AI28,"세이프","이룸")) -> 세이프 | AK28: =MAX('KT 합산단가입력'!AF23:AH23) -> 0 | AL28: =IF('KT 합산단가입력'!AF23=입력용!AK28,"MNS",IF('KT 합산단가입력'!AG23=입력용!AK28,"세이프","이룸")) -> MNS | AM28: =MAX('KT 합산단가입력'!AI23:AK23) -> 0 | AN28: =IF('KT 합산단가입력'!AI23=입력용!AM28,"MNS",IF('KT 합산단가입력'!AJ23=입력용!AM28,"세이프","이룸")) -> MNS | AO28: =C28 -> 아이폰16+ 128G | AP28: =MAX('LG 합산단가입력'!Z23:AB23) -> 90000 | AQ28: =IF('LG 합산단가입력'!Z23=입력용!AP28,"마라톤",IF('LG 합산단가입력'!AA23=입력용!AP28,"골드","충청")) -> 골드 | AR28: =MAX('LG 합산단가입력'!AC23:AE23) -> 30000 | AS28: =IF('LG 합산단가입력'!AC23=입력용!AR28,"마라톤",IF('LG 합산단가입력'!AD23=입력용!AR28,"골드","충청")) -> 골드 | AT28: =MAX('LG 합산단가입력'!AG23:AI23) -> 0 | AU28: =IF('LG 합산단가입력'!AG23=입력용!AT28,"마라톤",IF('LG 합산단가입력'!AH23=입력용!AT28,"골드","충청")) -> 마라톤 | AV28: =MAX('LG 합산단가입력'!AJ23:AL23) -> 0 | AW28: =IF('LG 합산단가입력'!AJ23=입력용!AV28,"마라톤",IF('LG 합산단가입력'!AK23=입력용!AV28,"골드","충청")) -> 충청
C29: 아이폰16 프로 128G | D29: 1540000 | F29: 220000 | H29: =SUM(D29-F29-G29)-SUM(X29-R29) -> 1320000 | I29: =SUM(D29-F29)-SUM(AB29-S29) -> 1320000 | J29: 550000 | K29: 100000 | L29: =SUM(D29-J29-K29)-SUM(AG29-T29) -> 810000 | M29: =SUM(D29-J29)-SUM(AK29-U29) -> 910000 | N29: 450000 | P29: =SUM(D29-N29-O29)-SUM(AP29-V29) -> 980000 | Q29: =SUM(D29-N29)-SUM(AT29-W29) -> 1090000 | R29: 0 | S29: 0 | T29: 0 | U29: 0 | V29: 0 | W29: 0 | X29: =MAX(SK합산단가입력!W24:Y24) -> 0 | Y29: =IF(SK합산단가입력!W24=입력용!X29,"블루",IF(SK합산단가입력!X24=입력용!X29,"MSC","한음")) -> MSC | Z29: =MAX(SK합산단가입력!Z24:AB24) -> 20000 | AA29: =IF(SK합산단가입력!Z24=입력용!Z29,"블루",IF(SK합산단가입력!AA24=입력용!Z29,"MSC","한음")) -> 블루 | AB29: =MAX(SK합산단가입력!AD24:AF24) -> 0 | AC29: =IF(SK합산단가입력!AD24=입력용!AB29,"블루",IF(SK합산단가입력!AE24=입력용!AB29,"MSC","MSC")) -> MSC | AD29: =MAX(SK합산단가입력!AG24:AI24) -> 0 | AE29: =IF(SK합산단가입력!AG24=입력용!AD29,"블루",IF(SK합산단가입력!AH24=입력용!AD29,"MSC","한음")) -> MSC | AF29: =C29 -> 아이폰16 프로 128G | AG29: =MAX('KT 합산단가입력'!Y24:AA24) -> 80000 | AH29: =IF('KT 합산단가입력'!Y24=입력용!AG29,"MNS",IF('KT 합산단가입력'!Z24=입력용!AG29,"세이프","이룸")) -> 세이프 | AI29: =MAX('KT 합산단가입력'!AB24:AD24) -> 80000 | AJ29: =IF('KT 합산단가입력'!AB24=입력용!AI29,"MNS",IF('KT 합산단가입력'!AC24=입력용!AI29,"세이프","이룸")) -> 세이프 | AK29: =MAX('KT 합산단가입력'!AF24:AH24) -> 80000 | AL29: =IF('KT 합산단가입력'!AF24=입력용!AK29,"MNS",IF('KT 합산단가입력'!AG24=입력용!AK29,"세이프","이룸")) -> 세이프 | AM29: =MAX('KT 합산단가입력'!AI24:AK24) -> 80000 | AN29: =IF('KT 합산단가입력'!AI24=입력용!AM29,"MNS",IF('KT 합산단가입력'!AJ24=입력용!AM29,"세이프","이룸")) -> 세이프 | AO29: =C29 -> 아이폰16 프로 128G | AP29: =MAX('LG 합산단가입력'!Z24:AB24) -> 110000 | AQ29: =IF('LG 합산단가입력'!Z24=입력용!AP29,"마라톤",IF('LG 합산단가입력'!AA24=입력용!AP29,"골드","충청")) -> 마라톤 | AR29: =MAX('LG 합산단가입력'!AC24:AE24) -> 40000 | AS29: =IF('LG 합산단가입력'!AC24=입력용!AR29,"마라톤",IF('LG 합산단가입력'!AD24=입력용!AR29,"골드","충청")) -> 마라톤 | AT29: =MAX('LG 합산단가입력'!AG24:AI24) -> 0 | AU29: =IF('LG 합산단가입력'!AG24=입력용!AT29,"마라톤",IF('LG 합산단가입력'!AH24=입력용!AT29,"골드","충청")) -> 마라톤 | AV29: =MAX('LG 합산단가입력'!AJ24:AL24) -> 0 | AW29: =IF('LG 합산단가입력'!AJ24=입력용!AV29,"마라톤",IF('LG 합산단가입력'!AK24=입력용!AV29,"골드","충청")) -> 충청
C30: 아이폰16 프로맥스 256G | D30: 1892000 | F30: 220000 | H30: =SUM(D30-F30-G30)-SUM(X30-R30) -> 1672000 | I30: =SUM(D30-F30)-SUM(AB30-S30) -> 1672000 | J30: 550000 | K30: 100000 | L30: =SUM(D30-J30-K30)-SUM(AG30-T30) -> 1162000 | M30: =SUM(D30-J30)-SUM(AK30-U30) -> 1262000 | N30: 450000 | P30: =SUM(D30-N30-O30)-SUM(AP30-V30) -> 1332000 | Q30: =SUM(D30-N30)-SUM(AT30-W30) -> 1442000 | R30: 0 | S30: 0 | T30: 0 | U30: 0 | V30: 0 | W30: 0 | X30: =MAX(SK합산단가입력!W25:Y25) -> 0 | Y30: =IF(SK합산단가입력!W25=입력용!X30,"블루",IF(SK합산단가입력!X25=입력용!X30,"MSC","한음")) -> MSC | Z30: =MAX(SK합산단가입력!Z25:AB25) -> 20000 | AA30: =IF(SK합산단가입력!Z25=입력용!Z30,"블루",IF(SK합산단가입력!AA25=입력용!Z30,"MSC","한음")) -> 블루 | AB30: =MAX(SK합산단가입력!AD25:AF25) -> 0 | AC30: =IF(SK합산단가입력!AD25=입력용!AB30,"블루",IF(SK합산단가입력!AE25=입력용!AB30,"MSC","MSC")) -> MSC | AD30: =MAX(SK합산단가입력!AG25:AI25) -> 0 | AE30: =IF(SK합산단가입력!AG25=입력용!AD30,"블루",IF(SK합산단가입력!AH25=입력용!AD30,"MSC","한음")) -> MSC | AF30: =C30 -> 아이폰16 프로맥스 256G | AG30: =MAX('KT 합산단가입력'!Y25:AA25) -> 80000 | AH30: =IF('KT 합산단가입력'!Y25=입력용!AG30,"MNS",IF('KT 합산단가입력'!Z25=입력용!AG30,"세이프","이룸")) -> 세이프 | AI30: =MAX('KT 합산단가입력'!AB25:AD25) -> 80000 | AJ30: =IF('KT 합산단가입력'!AB25=입력용!AI30,"MNS",IF('KT 합산단가입력'!AC25=입력용!AI30,"세이프","이룸")) -> 세이프 | AK30: =MAX('KT 합산단가입력'!AF25:AH25) -> 80000 | AL30: =IF('KT 합산단가입력'!AF25=입력용!AK30,"MNS",IF('KT 합산단가입력'!AG25=입력용!AK30,"세이프","이룸")) -> 세이프 | AM30: =MAX('KT 합산단가입력'!AI25:AK25) -> 80000 | AN30: =IF('KT 합산단가입력'!AI25=입력용!AM30,"MNS",IF('KT 합산단가입력'!AJ25=입력용!AM30,"세이프","이룸")) -> 세이프 | AO30: =C30 -> 아이폰16 프로맥스 256G | AP30: =MAX('LG 합산단가입력'!Z25:AB25) -> 110000 | AQ30: =IF('LG 합산단가입력'!Z25=입력용!AP30,"마라톤",IF('LG 합산단가입력'!AA25=입력용!AP30,"골드","충청")) -> 마라톤 | AR30: =MAX('LG 합산단가입력'!AC25:AE25) -> 40000 | AS30: =IF('LG 합산단가입력'!AC25=입력용!AR30,"마라톤",IF('LG 합산단가입력'!AD25=입력용!AR30,"골드","충청")) -> 마라톤 | AT30: =MAX('LG 합산단가입력'!AG25:AI25) -> 0 | AU30: =IF('LG 합산단가입력'!AG25=입력용!AT30,"마라톤",IF('LG 합산단가입력'!AH25=입력용!AT30,"골드","충청")) -> 마라톤 | AV30: =MAX('LG 합산단가입력'!AJ25:AL25) -> 0 | AW30: =IF('LG 합산단가입력'!AJ25=입력용!AV30,"마라톤",IF('LG 합산단가입력'!AK25=입력용!AV30,"골드","충청")) -> 충청
C31: 갤럭시 S25FE | D31: 946000 | F31: 500000 | H31: =SUM(D31-F31-G31)-SUM(X31-R31) -> -214000 | I31: =SUM(D31-F31)-SUM(AB31-S31) -> -4000 | J31: 500000 | L31: =SUM(D31-J31-K31)-SUM(AG31-T31) -> 36000 | M31: =SUM(D31-J31)-SUM(AK31-U31) -> 66000 | N31: 500000 | P31: =SUM(D31-N31-O31)-SUM(AP31-V31) -> -274000 | Q31: =SUM(D31-N31)-SUM(AT31-W31) -> 26000 | R31: 0 | S31: 0 | T31: 0 | U31: 0 | V31: 0 | W31: 0 | X31: =MAX(SK합산단가입력!W26:Y26) -> 660000 | Y31: =IF(SK합산단가입력!W26=입력용!X31,"블루",IF(SK합산단가입력!X26=입력용!X31,"MSC","한음")) -> 블루 | Z31: =MAX(SK합산단가입력!Z26:AB26) -> 560000 | AA31: =IF(SK합산단가입력!Z26=입력용!Z31,"블루",IF(SK합산단가입력!AA26=입력용!Z31,"MSC","한음")) -> 블루 | AB31: =MAX(SK합산단가입력!AD26:AF26) -> 450000 | AC31: =IF(SK합산단가입력!AD26=입력용!AB31,"블루",IF(SK합산단가입력!AE26=입력용!AB31,"MSC","MSC")) -> 블루 | AD31: =MAX(SK합산단가입력!AG26:AI26) -> 300000 | AE31: =IF(SK합산단가입력!AG26=입력용!AD31,"블루",IF(SK합산단가입력!AH26=입력용!AD31,"MSC","한음")) -> 블루 | AF31: =C31 -> 갤럭시 S25FE | AG31: =MAX('KT 합산단가입력'!Y26:AA26) -> 410000 | AH31: =IF('KT 합산단가입력'!Y26=입력용!AG31,"MNS",IF('KT 합산단가입력'!Z26=입력용!AG31,"세이프","이룸")) -> 이룸 | AI31: =MAX('KT 합산단가입력'!AB26:AD26) -> 440000 | AJ31: =IF('KT 합산단가입력'!AB26=입력용!AI31,"MNS",IF('KT 합산단가입력'!AC26=입력용!AI31,"세이프","이룸")) -> 이룸 | AK31: =MAX('KT 합산단가입력'!AF26:AH26) -> 380000 | AL31: =IF('KT 합산단가입력'!AF26=입력용!AK31,"MNS",IF('KT 합산단가입력'!AG26=입력용!AK31,"세이프","이룸")) -> 이룸 | AM31: =MAX('KT 합산단가입력'!AI26:AK26) -> 410000 | AN31: =IF('KT 합산단가입력'!AI26=입력용!AM31,"MNS",IF('KT 합산단가입력'!AJ26=입력용!AM31,"세이프","이룸")) -> 이룸 | AO31: =C31 -> 갤럭시 S25FE | AP31: =MAX('LG 합산단가입력'!Z26:AB26) -> 720000 | AQ31: =IF('LG 합산단가입력'!Z26=입력용!AP31,"마라톤",IF('LG 합산단가입력'!AA26=입력용!AP31,"골드","충청")) -> 골드 | AR31: =MAX('LG 합산단가입력'!AC26:AE26) -> 710000 | AS31: =IF('LG 합산단가입력'!AC26=입력용!AR31,"마라톤",IF('LG 합산단가입력'!AD26=입력용!AR31,"골드","충청")) -> 골드 | AT31: =MAX('LG 합산단가입력'!AG26:AI26) -> 420000 | AU31: =IF('LG 합산단가입력'!AG26=입력용!AT31,"마라톤",IF('LG 합산단가입력'!AH26=입력용!AT31,"골드","충청")) -> 골드 | AV31: =MAX('LG 합산단가입력'!AJ26:AL26) -> 410000 | AW31: =IF('LG 합산단가입력'!AJ26=입력용!AV31,"마라톤",IF('LG 합산단가입력'!AK26=입력용!AV31,"골드","충청")) -> 골드
C32: 퀀텀6(A566) | D32: 618200 | F32: 357000 | G32: 0 | H32: =SUM(D32-F32-G32)-SUM(X32-R32) -> -138800 | I32: =SUM(D32-F32)-SUM(AB32-S32) -> 111200 | L32: =SUM(D32-J32-K32)-SUM(AG32-T32) -> 598200 | M32: =SUM(D32-J32)-SUM(AK32-U32) -> 618200 | P32: =SUM(D32-N32-O32)-SUM(AP32-V32) -> 558200 | Q32: =SUM(D32-N32)-SUM(AT32-W32) -> 558200 | R32: 0 | S32: 0 | T32: 0 | U32: 0 | V32: 0 | W32: 0 | X32: =MAX(SK합산단가입력!W27:Y27) -> 400000 | Y32: =IF(SK합산단가입력!W27=입력용!X32,"블루",IF(SK합산단가입력!X27=입력용!X32,"MSC","한음")) -> MSC | Z32: =MAX(SK합산단가입력!Z27:AB27) -> 600000 | AA32: =IF(SK합산단가입력!Z27=입력용!Z32,"블루",IF(SK합산단가입력!AA27=입력용!Z32,"MSC","한음")) -> MSC | AB32: =MAX(SK합산단가입력!AD27:AF27) -> 150000 | AC32: =IF(SK합산단가입력!AD27=입력용!AB32,"블루",IF(SK합산단가입력!AE27=입력용!AB32,"MSC","MSC")) -> MSC | AD32: =MAX(SK합산단가입력!AG27:AI27) -> 400000 | AE32: =IF(SK합산단가입력!AG27=입력용!AD32,"블루",IF(SK합산단가입력!AH27=입력용!AD32,"MSC","한음")) -> MSC | AF32: =C32 -> 퀀텀6(A566) | AG32: =MAX('KT 합산단가입력'!Y27:AA27) -> 20000 | AH32: =IF('KT 합산단가입력'!Y27=입력용!AG32,"MNS",IF('KT 합산단가입력'!Z27=입력용!AG32,"세이프","이룸")) -> MNS | AI32: =MAX('KT 합산단가입력'!AB27:AD27) -> 40000 | AJ32: =IF('KT 합산단가입력'!AB27=입력용!AI32,"MNS",IF('KT 합산단가입력'!AC27=입력용!AI32,"세이프","이룸")) -> MNS | AK32: =MAX('KT 합산단가입력'!AF27:AH27) -> 0 | AL32: =IF('KT 합산단가입력'!AF27=입력용!AK32,"MNS",IF('KT 합산단가입력'!AG27=입력용!AK32,"세이프","이룸")) -> MNS | AM32: =MAX('KT 합산단가입력'!AI27:AK27) -> 20000 | AN32: =IF('KT 합산단가입력'!AI27=입력용!AM32,"MNS",IF('KT 합산단가입력'!AJ27=입력용!AM32,"세이프","이룸")) -> MNS | AO32: =C32 -> 퀀텀6(A566) | AP32: =MAX('LG 합산단가입력'!Z27:AB27) -> 60000 | AQ32: =IF('LG 합산단가입력'!Z27=입력용!AP32,"마라톤",IF('LG 합산단가입력'!AA27=입력용!AP32,"골드","충청")) -> 충청 | AR32: =MAX('LG 합산단가입력'!AC27:AE27) -> 30000 | AS32: =IF('LG 합산단가입력'!AC27=입력용!AR32,"마라톤",IF('LG 합산단가입력'!AD27=입력용!AR32,"골드","충청")) -> 충청 | AT32: =MAX('LG 합산단가입력'!AG27:AI27) -> 60000 | AU32: =IF('LG 합산단가입력'!AG27=입력용!AT32,"마라톤",IF('LG 합산단가입력'!AH27=입력용!AT32,"골드","충청")) -> 충청 | AV32: =MAX('LG 합산단가입력'!AJ27:AL27) -> 30000 | AW32: =IF('LG 합산단가입력'!AJ27=입력용!AV32,"마라톤",IF('LG 합산단가입력'!AK27=입력용!AV32,"골드","충청")) -> 충청
